Workbook

Sheet 00_개요
A1: KIIT 논문 통계 재현 워크북
A2: 논문에 보고된 모든 통계량을 원자료 975개 평가쌍에서 엑셀 수식으로 재계산한다. 모든 결과 셀은 하드코딩이 아니라 수식이며, 입력값을 바꾸면 전체가 다시 계산된다.
A4: 데이터 규모
A5: 평가쌍 | B5: 975 = 레퍼런스 5종 x 로컬 모델 3종 x 문서 65건
A6: ADR 원문 | B6: 520개 = 8개 모델 x 65건
A7: 지표 | B7: 12개 (어휘 6 + 의미 3 + 구조 3)
A8: 설계 | B8: 완전 균형 요인설계, 결측 없음
A10: 색상 규약
A11: 파란 글씨 | B11: 입력값(원자료 또는 논문에서 가져온 상수). 여기만 수정한다.
A12: 검정 글씨 | B12: 수식으로 계산된 값. 직접 수정하지 않는다.
A13: 노란 배경 | B13: 논문에 인쇄된 핵심 수치에 해당하는 셀
A15: 시트 구성
A16: 시트 | B16: 내용 | C16: 논문 대응
A17: 01_원자료 | B17: 975행 x 12지표. Overall Score와 순위를 수식으로 산출 | C17: 분석 원자료
A18: 02_지표정의 | B18: 12개 지표의 산식 정의, 그룹 가중치, 표기 방언 처리 | C18: 3.2, 표 1
A19: 03_가중치민감도 | B19: 가중치 6개 시나리오에 대한 결론 안정성 검증 | C19: 표 3, 4.1
A20: 03B_시나리오점수 | B20: 시나리오별 975쌍 점수·순위 (Spearman rho 계산용) | C20: 표 3
A21: 04_교차표 | B21: 레퍼런스x모델 5x3 셀 평균과 이중 중심화 잔차 | C21: 4.2 공통 입력
A22: 05_이원분산분석 | B22: 평방합 분해 → eta² (레퍼런스/모델/상호작용) | C22: 4.2
A23: 05B_가정검정 | B23: 셀별 정규성(왜도·첨도·JB)과 Levene 등분산성 검정 | C23: 3.4
A24: 06_ICC | B24: 문서 확률효과 분산성분과 급내상관 | C24: 4.2 강건성
A25: 07_관대함변별력 | B25: 레퍼런스의 두 축(관대함, 변별력) 분해 | C25: 표 4
A26: 08_KW_Holm | B26: Kruskal-Wallis + 쌍별 Mann-Whitney + Holm 보정 | C26: 표 5
A27: 09_12지표교차표 | B27: 15개 조합 x 12지표 평균 | C27: 표 6
... A35: 재현성 검증 결과 | B35: 논문 인쇄값 vs 워크북 계산값 자동 대조 | C35: 전체 검증
A36: 자동 대조 재현율 | B36: ='14_논문대조'!B92 -> 1
A37: 불일치 항목 수 | B37: ='14_논문대조'!B91 -> 0
A39: 독립 재구현 검증: 본 워크북의 원자료를 만들기 위해 구조 지표 산출 코드를 원 구현과 무관하게 다시 작성하고, 원 파이프라인과 동일한 조건(ATX 전용 파서)에서 돌린 결과가 기존 산출 파일과 최대 5.6e-17(배정밀도 한계) 차이로 일치하였다. 따라서 재계산 절차 자체가 원 구현을 정확히 재현한다.
A40: 문서 식별자 대조: adrs/ 원문의 문서번호와 산출 파일의 document_id는 서로 다른 체계를 쓴다. Markdown Awareness 값 15개를 지문으로 삼아 1:1 대응을 복원했으며, 65건 전부 L1 오차 0.0으로 유일하게 매칭되었다.
A42: 엑셀로 재현할 수 없는 항목
A43: 혼합모형(LMM)의 REML 추정은 엑셀 함수로 구현할 수 없다. 다만 본 연구는 완전 균형설계이므로 적률법 분산성분 추정이 REML 결과와 일치하며(06_ICC에서 확인), BERTScore·SBERT 등 임베딩 기반 지표는 신경망 추론이 필요하므로 01_원자료에 입력값으로 수록하였다.
A44: p값은 대표본 정규근사(NORMSDIST)와 카이제곱 분포(CHIDIST)를 사용한다. |z|가 13을 넘는 경우 부동소수점 하한 때문에 p가 0으로 표시되나 실제로는 극히 작은 값이다.
A46: 출처
A47: 원자료: similarity_{chatgpt|claude|gemini|mistral|qwen3_6}_as_reference.xlsx (5개 파일, 각 195행)
A48: 구조 지표 2종(MA, TEDS_doc): adrs/ 520개 원문에서 Setext·ATX 양쪽을 인식하는 파서로 전수 재계산
A49: 출력 어휘량: adrs/ 원문 토큰 수 직접 계수 / 로컬 상호 합의도: local_local_teds.csv
A50: 원 구현: calculate_similarity.py (KIIT_paper_source_code/src)

Sheet 01_원자료
A1: document_id | B1: reference_model | C1: comparison_model | D1: f1_score | E1: rouge1 | F1: rouge2 | G1: rougeL | H1: bleu_score | I1: tfidf_similarity | J1: bertscore | K1: sts_score | L1: moverscore | M1: markdown_awareness_similarity | N1: teds_document_structure_similarity | O1: teds_table_structure_similarity | P1: lex_mean | Q1: sem_mean | R1: str_mean | S1: overall_score | T1: 동일계열 | U1: 문서형식 | V1: 전체평균순위 | W1: pool순위_G:M | X1: pool순위_G:Q | Y1: pool순위_M:Q | Z1: 셀내 순위 | AA1: Levene Z=|y−셀중앙값| | AB1: 잔차 y−셀평균
A2: PAT-01 | B2: chatgpt | C2: gemma | D2: 0.25144509 | E2: 0.28193833 | F2: 0.10666667 | G2: 0.24669604 | H2: 0.20082965 | I2: 0.2258474 | J2: 0.63084064 | K2: 0.57586197 | L2: 0.73172974 | M2: 0.43589744 | N2: 0.18269231 | O2: 1 | P2: =AVERAGE(D2:I2) -> 0.21890386 | Q2: =AVERAGE(J2:L2) -> 0.64614412 | R2: =AVERAGE(M2:O2) -> 0.53952991 | S2: ='02_지표정의'!$C$22*P2+'02_지표정의'!$C$23*Q2+'02_지표정의'!$C$24*R2 -> 0.52338109 | T2: =IF(OR(AND(B2="gemini",C2="gemma"),AND(B2="qwen3_6",C2="qwen"),AND(B2="mistral",C2="ministral")),1,0) -> 0 | U2: =IF(LEFT(A2,3)="PAT","특허","보고서") -> 특허 | V2: =COUNTIF($S$2:$S$976,"<"&S2)+(COUNTIF($S$2:$S$976,"="&S2)+1)/2 -> 113 | W2: =IF(C2="qwen",0,COUNTIFS($C$2:$C$976,"<>qwen",$S$2:$S$976,"<"&S2)+1) -> 102 | X2: =IF(C2="ministral",0,COUNTIFS($C$2:$C$976,"<>ministral",$S$2:$S$976,"<"&S2)+1) -> 21 | Y2: =IF(C2="gemma",0,COUNTIFS($C$2:$C$976,"<>gemma",$S$2:$S$976,"<"&S2)+1) -> 0 | Z2: =COUNTIFS($B$2:$B$976,B2,$C$2:$C$976,C2,$S$2:$S$976,"<"&S2)+1 -> 9 | AA2: =ABS(S2-SUMPRODUCT(('05B_가정검정'!$A$5:$A$19=B2)*('05B_가정검정'!$B$5:$B$19=C2)*'05B_가정검정'!$E$5:$E$19)) -> 0.034022611 | AB2: =S2-AVERAGEIFS($S$2:$S$976,$B$2:$B$976,B2,$C$2:$C$976,C2) -> -0.029170071
A3: PAT-01 | B3: chatgpt | C3: ministral | D3: 0.28382838 | E3: 0.33093525 | F3: 0.13043478 | G3: 0.28776978 | H3: 0.14158547 | I3: 0.30670945 | J3: 0.65374856 | K3: 0.6648825 | L3: 0.79131049 | M3: 0.47311828 | N3: 0 | O3: 1 | P3: =AVERAGE(D3:I3) -> 0.24687719 | Q3: =AVERAGE(J3:L3) -> 0.70331385 | R3: =AVERAGE(M3:O3) -> 0.49103943 | S3: ='02_지표정의'!$C$22*P3+'02_지표정의'!$C$23*Q3+'02_지표정의'!$C$24*R3 -> 0.53773047 | T3: =IF(OR(AND(B3="gemini",C3="gemma"),AND(B3="qwen3_6",C3="qwen"),AND(B3="mistral",C3="ministral")),1,0) -> 0 | U3: =IF(LEFT(A3,3)="PAT","특허","보고서") -> 특허 | V3: =COUNTIF($S$2:$S$976,"<"&S3)+(COUNTIF($S$2:$S$976,"="&S3)+1)/2 -> 161 | W3: =IF(C3="qwen",0,COUNTIFS($C$2:$C$976,"<>qwen",$S$2:$S$976,"<"&S3)+1) -> 141 | X3: =IF(C3="ministral",0,COUNTIFS($C$2:$C$976,"<>ministral",$S$2:$S$976,"<"&S3)+1) -> 0 | Y3: =IF(C3="gemma",0,COUNTIFS($C$2:$C$976,"<>gemma",$S$2:$S$976,"<"&S3)+1) -> 146 | Z3: =COUNTIFS($B$2:$B$976,B3,$C$2:$C$976,C3,$S$2:$S$976,"<"&S3)+1 -> 37 | AA3: =ABS(S3-SUMPRODUCT(('05B_가정검정'!$A$5:$A$19=B3)*('05B_가정검정'!$B$5:$B$19=C3)*'05B_가정검정'!$E$5:$E$19)) -> 0.0064380488 | AB3: =S3-AVERAGEIFS($S$2:$S$976,$B$2:$B$976,B3,$C$2:$C$976,C3) -> 0.010181438
A4: PAT-01 | B4: chatgpt | C4: qwen | D4: 0.24815362 | E4: 0.42056075 | F4: 0.12264151 | G4: 0.30841121 | H4: 0.1820685 | I4: 0.35395534 | J4: 0.66989183 | K4: 0.55981052 | L4: 0.71544087 | M4: 0.37948718 | N4: 0 | O4: 1 | P4: =AVERAGE(D4:I4) -> 0.27263182 | Q4: =AVERAGE(J4:L4) -> 0.64838107 | R4: =AVERAGE(M4:O4) -> 0.45982906 | S4: ='02_지표정의'!$C$22*P4+'02_지표정의'!$C$23*Q4+'02_지표정의'!$C$24*R4 -> 0.50723802 | T4: =IF(OR(AND(B4="gemini",C4="gemma"),AND(B4="qwen3_6",C4="qwen"),AND(B4="mistral",C4="ministral")),1,0) -> 0 | U4: =IF(LEFT(A4,3)="PAT","특허","보고서") -> 특허 | V4: =COUNTIF($S$2:$S$976,"<"&S4)+(COUNTIF($S$2:$S$976,"="&S4)+1)/2 -> 60 | W4: =IF(C4="qwen",0,COUNTIFS($C$2:$C$976,"<>qwen",$S$2:$S$976,"<"&S4)+1) -> 0 | X4: =IF(C4="ministral",0,COUNTIFS($C$2:$C$976,"<>ministral",$S$2:$S$976,"<"&S4)+1) -> 14 | Y4: =IF(C4="gemma",0,COUNTIFS($C$2:$C$976,"<>gemma",$S$2:$S$976,"<"&S4)+1) -> 53 | Z4: =COUNTIFS($B$2:$B$976,B4,$C$2:$C$976,C4,$S$2:$S$976,"<"&S4)+1 -> 2 | AA4: =ABS(S4-SUMPRODUCT(('05B_가정검정'!$A$5:$A$19=B4)*('05B_가정검정'!$B$5:$B$19=C4)*'05B_가정검정'!$E$5:$E$19)) -> 0.045785499 | AB4: =S4-AVERAGEIFS($S$2:$S$976,$B$2:$B$976,B4,$C$2:$C$976,C4) -> -0.049214466
A5: PAT-01 | B5: claude | C5: gemma | D5: 0.26677995 | E5: 0.30246914 | F5: 0.074534161 | G5: 0.17901235 | H5: 0.28403318 | I5: 0.1860384 | J5: 0.68962661 | K5: 0.62263356 | L5: 0.85854659 | M5: 0.56707317 | N5: 0.5212766 | O5: 1 | P5: =AVERAGE(D5:I5) -> 0.21547786 | Q5: =AVERAGE(J5:L5) -> 0.72360225 | R5: =AVERAGE(M5:O5) -> 0.69611659 | S5: ='02_지표정의'!$C$22*P5+'02_지표정의'!$C$23*Q5+'02_지표정의'!$C$24*R5 -> 0.61235739 | T5: =IF(OR(AND(B5="gemini",C5="gemma"),AND(B5="qwen3_6",C5="qwen"),AND(B5="mistral",C5="ministral")),1,0) -> 0 | U5: =IF(LEFT(A5,3)="PAT","특허","보고서") -> 특허 | V5: =COUNTIF($S$2:$S$976,"<"&S5)+(COUNTIF($S$2:$S$976,"="&S5)+1)/2 -> 448 | W5: =IF(C5="qwen",0,COUNTIFS($C$2:$C$976,"<>qwen",$S$2:$S$976,"<"&S5)+1) -> 365 | X5: =IF(C5="ministral",0,COUNTIFS($C$2:$C$976,"<>ministral",$S$2:$S$976,"<"&S5)+1) -> 191 | Y5: =IF(C5="gemma",0,COUNTIFS($C$2:$C$976,"<>gemma",$S$2:$S$976,"<"&S5)+1) -> 0 | Z5: =COUNTIFS($B$2:$B$976,B5,$C$2:$C$976,C5,$S$2:$S$976,"<"&S5)+1 -> 18 | AA5: =ABS(S5-SUMPRODUCT(('05B_가정검정'!$A$5:$A$19=B5)*('05B_가정검정'!$B$5:$B$19=C5)*'05B_가정검정'!$E$5:$E$19)) -> 0.015691569 | AB5: =S5-AVERAGEIFS($S$2:$S$976,$B$2:$B$976,B5,$C$2:$C$976,C5) -> -0.018945312
A6: PAT-01 | B6: claude | C6: ministral | D6: 0.22914757 | E6: 0.272 | F6: 0.091152815 | G6: 0.20266667 | H6: 0.2392412 | I6: 0.17376613 | J6: 0.70776473 | K6: 0.64362822 | L6: 0.84404955 | M6: 0.53046595 | N6: 0.52713178 | O6: 1 | P6: =AVERAGE(D6:I6) -> 0.20132906 | Q6: =AVERAGE(J6:L6) -> 0.73181417 | R6: =AVERAGE(M6:O6) -> 0.68586591 | S6: ='02_지표정의'!$C$22*P6+'02_지표정의'!$C$23*Q6+'02_지표정의'!$C$24*R6 -> 0.60963526 | T6: =IF(OR(AND(B6="gemini",C6="gemma"),AND(B6="qwen3_6",C6="qwen"),AND(B6="mistral",C6="ministral")),1,0) -> 0 | U6: =IF(LEFT(A6,3)="PAT","특허","보고서") -> 특허 | V6: =COUNTIF($S$2:$S$976,"<"&S6)+(COUNTIF($S$2:$S$976,"="&S6)+1)/2 -> 428 | W6: =IF(C6="qwen",0,COUNTIFS($C$2:$C$976,"<>qwen",$S$2:$S$976,"<"&S6)+1) -> 349 | X6: =IF(C6="ministral",0,COUNTIFS($C$2:$C$976,"<>ministral",$S$2:$S$976,"<"&S6)+1) -> 0 | Y6: =IF(C6="gemma",0,COUNTIFS($C$2:$C$976,"<>gemma",$S$2:$S$976,"<"&S6)+1) -> 326 | Z6: =COUNTIFS($B$2:$B$976,B6,$C$2:$C$976,C6,$S$2:$S$976,"<"&S6)+1 -> 43 | AA6: =ABS(S6-SUMPRODUCT(('05B_가정검정'!$A$5:$A$19=B6)*('05B_가정검정'!$B$5:$B$19=C6)*'05B_가정검정'!$E$5:$E$19)) -> 0.018806408 | AB6: =S6-AVERAGEIFS($S$2:$S$976,$B$2:$B$976,B6,$C$2:$C$976,C6) -> 0.03474448
A7: PAT-01 | B7: claude | C7: qwen | D7: 0.25817556 | E7: 0.36012862 | F7: 0.11650485 | G7: 0.25723473 | H7: 0.3204868 | I7: 0.24505675 | J7: 0.69981071 | K7: 0.61108906 | L7: 0.84354566 | M7: 0.61538462 | N7: 0.54901961 | O7: 1 | P7: =AVERAGE(D7:I7) -> 0.25959788 | Q7: =AVERAGE(J7:L7) -> 0.71814847 | R7: =AVERAGE(M7:O7) -> 0.72146807 | S7: ='02_지표정의'!$C$22*P7+'02_지표정의'!$C$23*Q7+'02_지표정의'!$C$24*R7 -> 0.62760022 | T7: =IF(OR(AND(B7="gemini",C7="gemma"),AND(B7="qwen3_6",C7="qwen"),AND(B7="mistral",C7="ministral")),1,0) -> 0 | U7: =IF(LEFT(A7,3)="PAT","특허","보고서") -> 특허 | V7: =COUNTIF($S$2:$S$976,"<"&S7)+(COUNTIF($S$2:$S$976,"="&S7)+1)/2 -> 519 | W7: =IF(C7="qwen",0,COUNTIFS($C$2:$C$976,"<>qwen",$S$2:$S$976,"<"&S7)+1) -> 0 | X7: =IF(C7="ministral",0,COUNTIFS($C$2:$C$976,"<>ministral",$S$2:$S$976,"<"&S7)+1) -> 229 | Y7: =IF(C7="gemma",0,COUNTIFS($C$2:$C$976,"<>gemma",$S$2:$S$976,"<"&S7)+1) -> 392 | Z7: =COUNTIFS($B$2:$B$976,B7,$C$2:$C$976,C7,$S$2:$S$976,"<"&S7)+1 -> 11 | AA7: =ABS(S7-SUMPRODUCT(('05B_가정검정'!$A$5:$A$19=B7)*('05B_가정검정'!$B$5:$B$19=C7)*'05B_가정검정'!$E$5:$E$19)) -> 0.0360771 | AB7: =S7-AVERAGEIFS($S$2:$S$976,$B$2:$B$976,B7,$C$2:$C$976,C7) -> -0.030822791
A8: PAT-01 | B8: gemini | C8: gemma | D8: 0.26373626 | E8: 0.30769231 | F8: 0.11872146 | G8: 0.23529412 | H8: 0.28200643 | I8: 0.16971891 | J8: 0.73920992 | K8: 0.6974853 | L8: 0.85993135 | M8: 0.90654206 | N8: 0.91666667 | O8: 1 | P8: =AVERAGE(D8:I8) -> 0.22952825 | Q8: =AVERAGE(J8:L8) -> 0.76554219 | R8: =AVERAGE(M8:O8) -> 0.94106957 | S8: ='02_지표정의'!$C$22*P8+'02_지표정의'!$C$23*Q8+'02_지표정의'!$C$24*R8 -> 0.71977399 | T8: =IF(OR(AND(B8="gemini",C8="gemma"),AND(B8="qwen3_6",C8="qwen"),AND(B8="mistral",C8="ministral")),1,0) -> 1 | U8: =IF(LEFT(A8,3)="PAT","특허","보고서") -> 특허 | V8: =COUNTIF($S$2:$S$976,"<"&S8)+(COUNTIF($S$2:$S$976,"="&S8)+1)/2 -> 878 | W8: =IF(C8="qwen",0,COUNTIFS($C$2:$C$976,"<>qwen",$S$2:$S$976,"<"&S8)+1) -> 586 | X8: =IF(C8="ministral",0,COUNTIFS($C$2:$C$976,"<>ministral",$S$2:$S$976,"<"&S8)+1) -> 553 | Y8: =IF(C8="gemma",0,COUNTIFS($C$2:$C$976,"<>gemma",$S$2:$S$976,"<"&S8)+1) -> 0 | Z8: =COUNTIFS($B$2:$B$976,B8,$C$2:$C$976,C8,$S$2:$S$976,"<"&S8)+1 -> 24 | AA8: =ABS(S8-SUMPRODUCT(('05B_가정검정'!$A$5:$A$19=B8)*('05B_가정검정'!$B$5:$B$19=C8)*'05B_가정검정'!$E$5:$E$19)) -> 0.0096580845 | AB8: =S8-AVERAGEIFS($S$2:$S$976,$B$2:$B$976,B8,$C$2:$C$976,C8) -> 0.0021221938
A9: PAT-01 | B9: gemini | C9: ministral | D9: 0.23465211 | E9: 0.27941176 | F9: 0.1037037 | G9: 0.24264706 | H9: 0.16846332 | I9: 0.1759258 | J9: 0.74590856 | K9: 0.74663408 | L9: 0.8873062 | M9: 0.34767025 | N9: 0.42635659 | O9: 1 | P9: =AVERAGE(D9:I9) -> 0.20080063 | Q9: =AVERAGE(J9:L9) -> 0.79328295 | R9: =AVERAGE(M9:O9) -> 0.59134228 | S9: ='02_지표정의'!$C$22*P9+'02_지표정의'!$C$23*Q9+'02_지표정의'!$C$24*R9 -> 0.60410725 | T9: =IF(OR(AND(B9="gemini",C9="gemma"),AND(B9="qwen3_6",C9="qwen"),AND(B9="mistral",C9="ministral")),1,0) -> 0 | U9: =IF(LEFT(A9,3)="PAT","특허","보고서") -> 특허 | V9: =COUNTIF($S$2:$S$976,"<"&S9)+(COUNTIF($S$2:$S$976,"="&S9)+1)/2 -> 408 | W9: =IF(C9="qwen",0,COUNTIFS($C$2:$C$976,"<>qwen",$S$2:$S$976,"<"&S9)+1) -> 330 | X9: =IF(C9="ministral",0,COUNTIFS($C$2:$C$976,"<>ministral",$S$2:$S$976,"<"&S9)+1) -> 0 | Y9: =IF(C9="gemma",0,COUNTIFS($C$2:$C$976,"<>gemma",$S$2:$S$976,"<"&S9)+1) -> 310 | Z9: =COUNTIFS($B$2:$B$976,B9,$C$2:$C$976,C9,$S$2:$S$976,"<"&S9)+1 -> 35 | AA9: =ABS(S9-SUMPRODUCT(('05B_가정검정'!$A$5:$A$19=B9)*('05B_가정검정'!$B$5:$B$19=C9)*'05B_가정검정'!$E$5:$E$19)) -> 0.0055277592 | AB9: =S9-AVERAGEIFS($S$2:$S$976,$B$2:$B$976,B9,$C$2:$C$976,C9) -> 0.024708175
A10: PAT-01 | B10: gemini | C10: qwen | D10: 0.24378109 | E10: 0.38461538 | F10: 0.12621359 | G10: 0.27884615 | H10: 0.23965923 | I10: 0.26843241 | J10: 0.76145152 | K10: 0.69550728 | L10: 0.85429733 | M10: 0.5739645 | N10: 0.53921569 | O10: 1 | P10: =AVERAGE(D10:I10) -> 0.25692464 | Q10: =AVERAGE(J10:L10) -> 0.77041871 | R10: =AVERAGE(M10:O10) -> 0.70439339 | S10: ='02_지표정의'!$C$22*P10+'02_지표정의'!$C$23*Q10+'02_지표정의'!$C$24*R10 -> 0.64461104 | T10: =IF(OR(AND(B10="gemini",C10="gemma"),AND(B10="qwen3_6",C10="qwen"),AND(B10="mistral",C10="ministral")),1,0) -> 0 | U10: =IF(LEFT(A10,3)="PAT","특허","보고서") -> 특허 | V10: =COUNTIF($S$2:$S$976,"<"&S10)+(COUNTIF($S$2:$S$976,"="&S10)+1)/2 -> 595 | W10: =IF(C10="qwen",0,COUNTIFS($C$2:$C$976,"<>qwen",$S$2:$S$976,"<"&S10)+1) -> 0 | X10: =IF(C10="ministral",0,COUNTIFS($C$2:$C$976,"<>ministral",$S$2:$S$976,"<"&S10)+1) -> 286 | Y10: =IF(C10="gemma",0,COUNTIFS($C$2:$C$976,"<>gemma",$S$2:$S$976,"<"&S10)+1) -> 445 | Z10: =COUNTIFS($B$2:$B$976,B10,$C$2:$C$976,C10,$S$2:$S$976,"<"&S10)+1 -> 6 | AA10: =ABS(S10-SUMPRODUCT(('05B_가정검정'!$A$5:$A$19=B10)*('05B_가정검정'!$B$5:$B$19=C10)*'05B_가정검정'!$E$5:$E$19)) -> 0.047708806 | AB10: =S10-AVERAGEIFS($S$2:$S$976,$B$2:$B$976,B10,$C$2:$C$976,C10) -> -0.043625939
A11: PAT-01 | B11: mistral | C11: gemma | D11: 0.24849216 | E11: 0.25101215 | F11: 0.073469388 | G11: 0.21052632 | H11: 0.31677417 | I11: 0.19932074 | J11: 0.70184692 | K11: 0.54227748 | L11: 0.74642301 | M11: 0.5027027 | N11: 0.44545455 | O11: 1 | P11: =AVERAGE(D11:I11) -> 0.21659915 | Q11: =AVERAGE(J11:L11) -> 0.6635158 | R11: =AVERAGE(M11:O11) -> 0.64938575 | S11: ='02_지표정의'!$C$22*P11+'02_지표정의'!$C$23*Q11+'02_지표정의'!$C$24*R11 -> 0.56918695 | T11: =IF(OR(AND(B11="gemini",C11="gemma"),AND(B11="qwen3_6",C11="qwen"),AND(B11="mistral",C11="ministral")),1,0) -> 0 | U11: =IF(LEFT(A11,3)="PAT","특허","보고서") -> 특허 | V11: =COUNTIF($S$2:$S$976,"<"&S11)+(COUNTIF($S$2:$S$976,"="&S11)+1)/2 -> 281 | W11: =IF(C11="qwen",0,COUNTIFS($C$2:$C$976,"<>qwen",$S$2:$S$976,"<"&S11)+1) -> 229 | X11: =IF(C11="ministral",0,COUNTIFS($C$2:$C$976,"<>ministral",$S$2:$S$976,"<"&S11)+1) -> 111 | Y11: =IF(C11="gemma",0,COUNTIFS($C$2:$C$976,"<>gemma",$S$2:$S$976,"<"&S11)+1) -> 0 | Z11: =COUNTIFS($B$2:$B$976,B11,$C$2:$C$976,C11,$S$2:$S$976,"<"&S11)+1 -> 10 | AA11: =ABS(S11-SUMPRODUCT(('05B_가정검정'!$A$5:$A$19=B11)*('05B_가정검정'!$B$5:$B$19=C11)*'05B_가정검정'!$E$5:$E$19)) -> 0.070166 | AB11: =S11-AVERAGEIFS($S$2:$S$976,$B$2:$B$976,B11,$C$2:$C$976,C11) -> -0.053694668
A12: PAT-01 | B12: mistral | C12: ministral | D12: 0.30686406 | E12: 0.37583893 | F12: 0.16216216 | G12: 0.2885906 | H12: 0.27356377 | I12: 0.25737722 | J12: 0.71775166 | K12: 0.63988422 | L12: 0.78329372 | M12: 0.57706093 | N12: 0.63565891 | O12: 1 | P12: =AVERAGE(D12:I12) -> 0.27739946 | Q12: =AVERAGE(J12:L12) -> 0.7136432 | R12: =AVERAGE(M12:O12) -> 0.73757328 | S12: ='02_지표정의'!$C$22*P12+'02_지표정의'!$C$23*Q12+'02_지표정의'!$C$24*R12 -> 0.63476998 | T12: =IF(OR(AND(B12="gemini",C12="gemma"),AND(B12="qwen3_6",C12="qwen"),AND(B12="mistral",C12="ministral")),1,0) -> 1 | U12: =IF(LEFT(A12,3)="PAT","특허","보고서") -> 특허 | V12: =COUNTIF($S$2:$S$976,"<"&S12)+(COUNTIF($S$2:$S$976,"="&S12)+1)/2 -> 552 | W12: =IF(C12="qwen",0,COUNTIFS($C$2:$C$976,"<>qwen",$S$2:$S$976,"<"&S12)+1) -> 434 | X12: =IF(C12="ministral",0,COUNTIFS($C$2:$C$976,"<>ministral",$S$2:$S$976,"<"&S12)+1) -> 0 | Y12: =IF(C12="gemma",0,COUNTIFS($C$2:$C$976,"<>gemma",$S$2:$S$976,"<"&S12)+1) -> 416 | Z12: =COUNTIFS($B$2:$B$976,B12,$C$2:$C$976,C12,$S$2:$S$976,"<"&S12)+1 -> 54 | AA12: =ABS(S12-SUMPRODUCT(('05B_가정검정'!$A$5:$A$19=B12)*('05B_가정검정'!$B$5:$B$19=C12)*'05B_가정검정'!$E$5:$E$19)) -> 0.047848043 | AB12: =S12-AVERAGEIFS($S$2:$S$976,$B$2:$B$976,B12,$C$2:$C$976,C12) -> 0.053546703
A13: PAT-01 | B13: mistral | C13: qwen | D13: 0.23832924 | E13: 0.47008547 | F13: 0.15517241 | G13: 0.36752137 | H13: 0.31914738 | I13: 0.23680199 | J13: 0.71708491 | K13: 0.55676925 | L13: 0.75243566 | M13: 0.79459459 | N13: 0.80909091 | O13: 1 | P13: =AVERAGE(D13:I13) -> 0.29784298 | Q13: =AVERAGE(J13:L13) -> 0.67542994 | R13: =AVERAGE(M13:O13) -> 0.86789517 | S13: ='02_지표정의'!$C$22*P13+'02_지표정의'!$C$23*Q13+'02_지표정의'!$C$24*R13 -> 0.66727538 | T13: =IF(OR(AND(B13="gemini",C13="gemma"),AND(B13="qwen3_6",C13="qwen"),AND(B13="mistral",C13="ministral")),1,0) -> 0 | U13: =IF(LEFT(A13,3)="PAT","특허","보고서") -> 특허 | V13: =COUNTIF($S$2:$S$976,"<"&S13)+(COUNTIF($S$2:$S$976,"="&S13)+1)/2 -> 704 | W13: =IF(C13="qwen",0,COUNTIFS($C$2:$C$976,"<>qwen",$S$2:$S$976,"<"&S13)+1) -> 0 | X13: =IF(C13="ministral",0,COUNTIFS($C$2:$C$976,"<>ministral",$S$2:$S$976,"<"&S13)+1) -> 384 | Y13: =IF(C13="gemma",0,COUNTIFS($C$2:$C$976,"<>gemma",$S$2:$S$976,"<"&S13)+1) -> 518 | Z13: =COUNTIFS($B$2:$B$976,B13,$C$2:$C$976,C13,$S$2:$S$976,"<"&S13)+1 -> 49 | AA13: =ABS(S13-SUMPRODUCT(('05B_가정검정'!$A$5:$A$19=B13)*('05B_가정검정'!$B$5:$B$19=C13)*'05B_가정검정'!$E$5:$E$19)) -> 0.031669188 | AB13: =S13-AVERAGEIFS($S$2:$S$976,$B$2:$B$976,B13,$C$2:$C$976,C13) -> 0.03588651
... A976: RPT-34 | B976: qwen3_6 | C976: qwen | D976: 0.33737596 | E976: 0.39509954 | F976: 0.14746544 | G976: 0.22052067 | H976: 0.29746789 | I976: 0.38446099 | J976: 0.65799377 | K976: 0.69404336 | L976: 0.84398779 | M976: 0.90654206 | N976: 0.91666667 | O976: 1 | P976: =AVERAGE(D976:I976) -> 0.29706508 | Q976: =AVERAGE(J976:L976) -> 0.73200831 | R976: =AVERAGE(M976:O976) -> 0.94106957 | S976: ='02_지표정의'!$C$22*P976+'02_지표정의'!$C$23*Q976+'02_지표정의'!$C$24*R976 -> 0.71819111 | T976: =IF(OR(AND(B976="gemini",C976="gemma"),AND(B976="qwen3_6",C976="qwen"),AND(B976="mistral",C976="ministral")),1,0) -> 1 | U976: =IF(LEFT(A976,3)="PAT","특허","보고서") -> 보고서 | V976: =COUNTIF($S$2:$S$976,"<"&S976)+(COUNTIF($S$2:$S$976,"="&S976)+1)/2 -> 871 | W976: =IF(C976="qwen",0,COUNTIFS($C$2:$C$976,"<>qwen",$S$2:$S$976,"<"&S976)+1) -> 0 | X976: =IF(C976="ministral",0,COUNTIFS($C$2:$C$976,"<>ministral",$S$2:$S$976,"<"&S976)+1) -> 546 | Y976: =IF(C976="gemma",0,COUNTIFS($C$2:$C$976,"<>gemma",$S$2:$S$976,"<"&S976)+1) -> 617 | Z976: =COUNTIFS($B$2:$B$976,B976,$C$2:$C$976,C976,$S$2:$S$976,"<"&S976)+1 -> 50 | AA976: =ABS(S976-SUMPRODUCT(('05B_가정검정'!$A$5:$A$19=B976)*('05B_가정검정'!$B$5:$B$19=C976)*'05B_가정검정'!$E$5:$E$19)) -> 0.032561309 | AB976: =S976-AVERAGEIFS($S$2:$S$976,$B$2:$B$976,B976,$C$2:$C$976,C976) -> 0.035772373

Sheet 02_지표정의
A1: 지표 정의 및 Overall Score 산식
A2: 01_원자료 D~O열 12개 지표의 정의. 원 구현: calculate_similarity.py
A4: # | B4: 지표(컬럼) | C4: 그룹 | D4: 산식 / 정의 | E4: 범위
A5: 1 | B5: f1_score | C5: 어휘 | D5: 어휘 중복 F1. P=|공통토큰|/|후보토큰|, R=|공통토큰|/|기준토큰|, F1=2PR/(P+R) | E5: 0~1
A6: 2 | B6: rouge1 | C6: 어휘 | D6: ROUGE-1: unigram 재현율 기반 중복도 | E6: 0~1
A7: 3 | B7: rouge2 | C7: 어휘 | D7: ROUGE-2: bigram 중복도 | E7: 0~1
A8: 4 | B8: rougeL | C8: 어휘 | D8: ROUGE-L: 최장공통부분수열(LCS) 기반 F-measure | E8: 0~1
A9: 5 | B9: bleu_score | C9: 어휘 | D9: BLEU n=1~4 가중조합의 평균(smoothing 적용) | E9: 0~1
A10: 6 | B10: tfidf_similarity | C10: 어휘 | D10: TF-IDF 벡터 간 코사인 유사도 | E10: 0~1
A11: 7 | B11: bertscore | C11: 의미 | D11: BERTScore F1. 청크 분할 후 길이 가중 평균 | E11: 0~1
A12: 8 | B12: sts_score | C12: 의미 | D12: SBERT 임베딩 코사인 유사도의 양방향 best-match 길이가중 평균 | E12: 0~1
A13: 9 | B13: moverscore | C13: 의미 | D13: Word Mover 계열 거리 기반 유사도 | E13: 0~1
A14: 10 | B14: markdown_awareness_similarity | C14: 구조 | D14: MDEval Markdown Awareness. 마크다운을 HTML형 구조토큰 시퀀스로 변환 후 1 - Levenshtein(t1,t2)/max(|t1|,|t2|) | E14: 0~1
A15: 11 | B15: teds_document_structure_similarity | C15: 구조 | D15: TEDS(Tree Edit Distance-based Similarity) 문서판. 문서를 순서트리로 변환 후 1 - TED(T1,T2)/max(|T1|,|T2|). 삽입·삭제 비용=서브트리 크기, 치환 비용=라벨 불일치 시 1 | E15: 0~1
A16: 12 | B16: teds_table_structure_similarity | C16: 구조 | D16: TEDS 표판. 표를 table>tr>td 트리로 변환 후 양방향 best-match 평균. 양쪽 모두 표가 없으면 NaN, 한쪽만 있으면 0 | E16: 0~1
A19: 그룹 가중치 (Overall Score)
A20: 아래 세 값은 논문에서 채택한 가중치이며 03_가중치민감도에서 검증한다. 이 셀을 바꾸면 워크북 전체가 재계산된다.
A21: 그룹 | B21: 지표 수 | C21: 가중치
A22: lexical (어휘) | B22: 6 | C22: 0.2
A23: semantic (의미) | B23: 3 | C23: 0.45
A24: structure (구조) | B24: 3 | C24: 0.35
A25: 합계 | C25: =SUM(C22:C24) -> 1
A27: Overall Score 산식
A28: overall_score = w_lex x mean(어휘 6개) + w_sem x mean(의미 3개) + w_str x mean(구조 3개)
A29: = 01_원자료 P열 x C22 + Q열 x C23 + R열 x C24 (P/Q/R = 각 그룹 내 단순평균)
A30: 주의: overall_document_structure_similarity(=0.40·MA+0.40·TEDS_doc+0.20·TEDS_table)는 나머지 세 구조 지표의 가중평균이므로 이중계산을 피하기 위해 점수 산식에서 제외한다.
A32: 표기 방언 처리 (본 워크북 원자료의 전제)
A33: 구조 지표 2종(MA, TEDS_doc)은 마크다운 제목 표기 방언에 민감하다. Claude·GPT·Mistral 산출물은 Setext(제목 아래 = 또는 --- 반복), Gemini·Qwen3.6 및 로컬 3종은 ATX(# 접두) 방식을 사용한다.
A34: ATX만 인식하는 파서를 쓰면 Setext 문서의 계층이 소실되어 TEDS_doc가 0으로 절단된다(전체의 60.2%). 본 워크북 원자료는 두 방언을 모두 인식하는 파서로 전수 재계산한 값이다(0 비율 8.4%, 평균 0.2543 → 0.4783).

Sheet 03_가중치민감도
A1: 표 3. Overall Score 가중치 민감도 검증
A2: 가중치 조합을 바꿔도 모델 순위와 점수 서열이 유지되는지 확인한다. 분석단위: 975 평가쌍
A4: 시나리오 | B4: w_lex | C4: w_sem | D4: w_str | E4: Gemma 평균 | F4: Ministral 평균 | G4: Qwen 평균 | H4: 1위 모델 | I4: 2위 모델 | J4: 3위 모델 | K4: baseline 대비 Spearman rho
A5: baseline (20/45/35) | B5: 0.2 | C5: 0.45 | D5: 0.35 | E5: =AVERAGEIFS('03B_시나리오점수'!$E$5:$E$979,'01_원자료'!$C$2:$C$976,"gemma") -> 0.64647455 | F5: =AVERAGEIFS('03B_시나리오점수'!$E$5:$E$979,'01_원자료'!$C$2:$C$976,"ministral") -> 0.56458675 | G5: =AVERAGEIFS('03B_시나리오점수'!$E$5:$E$979,'01_원자료'!$C$2:$C$976,"qwen") -> 0.64338401 | H5: =INDEX({"Gemma","Ministral","Qwen"},MATCH(LARGE(E5:G5,1),E5:G5,0)) -> Gemma | I5: =INDEX({"Gemma","Ministral","Qwen"},MATCH(LARGE(E5:G5,2),E5:G5,0)) -> Qwen | J5: =INDEX({"Gemma","Ministral","Qwen"},MATCH(LARGE(E5:G5,3),E5:G5,0)) -> Ministral | K5: =CORREL('03B_시나리오점수'!$K$5:$K$979,'03B_시나리오점수'!$K$5:$K$979) -> 1
A6: lex_heavy (40/30/30) | B6: 0.4 | C6: 0.3 | D6: 0.3 | E6: =AVERAGEIFS('03B_시나리오점수'!$F$5:$F$979,'01_원자료'!$C$2:$C$976,"gemma") -> 0.54608747 | F6: =AVERAGEIFS('03B_시나리오점수'!$F$5:$F$979,'01_원자료'!$C$2:$C$976,"ministral") -> 0.47516189 | G6: =AVERAGEIFS('03B_시나리오점수'!$F$5:$F$979,'01_원자료'!$C$2:$C$976,"qwen") -> 0.5582378 | H6: =INDEX({"Gemma","Ministral","Qwen"},MATCH(LARGE(E6:G6,1),E6:G6,0)) -> Qwen | I6: =INDEX({"Gemma","Ministral","Qwen"},MATCH(LARGE(E6:G6,2),E6:G6,0)) -> Gemma | J6: =INDEX({"Gemma","Ministral","Qwen"},MATCH(LARGE(E6:G6,3),E6:G6,0)) -> Ministral | K6: =CORREL('03B_시나리오점수'!$K$5:$K$979,'03B_시나리오점수'!$L$5:$L$979) -> 0.98658159
A7: sem_heavy (20/50/30) | B7: 0.2 | C7: 0.5 | D7: 0.3 | E7: =AVERAGEIFS('03B_시나리오점수'!$G$5:$G$979,'01_원자료'!$C$2:$C$976,"gemma") -> 0.6456318 | F7: =AVERAGEIFS('03B_시나리오점수'!$G$5:$G$979,'01_원자료'!$C$2:$C$976,"ministral") -> 0.57683164 | G7: =AVERAGEIFS('03B_시나리오점수'!$G$5:$G$979,'01_원자료'!$C$2:$C$976,"qwen") -> 0.64610852 | H7: =INDEX({"Gemma","Ministral","Qwen"},MATCH(LARGE(E7:G7,1),E7:G7,0)) -> Qwen | I7: =INDEX({"Gemma","Ministral","Qwen"},MATCH(LARGE(E7:G7,2),E7:G7,0)) -> Gemma | J7: =INDEX({"Gemma","Ministral","Qwen"},MATCH(LARGE(E7:G7,3),E7:G7,0)) -> Ministral | K7: =CORREL('03B_시나리오점수'!$K$5:$K$979,'03B_시나리오점수'!$M$5:$M$979) -> 0.99818713
A8: struct_heavy (20/20/60) | B8: 0.2 | C8: 0.2 | D8: 0.6 | E8: =AVERAGEIFS('03B_시나리오점수'!$H$5:$H$979,'01_원자료'!$C$2:$C$976,"gemma") -> 0.65068827 | F8: =AVERAGEIFS('03B_시나리오점수'!$H$5:$H$979,'01_원자료'!$C$2:$C$976,"ministral") -> 0.50336231 | G8: =AVERAGEIFS('03B_시나리오점수'!$H$5:$H$979,'01_원자료'!$C$2:$C$976,"qwen") -> 0.62976146 | H8: =INDEX({"Gemma","Ministral","Qwen"},MATCH(LARGE(E8:G8,1),E8:G8,0)) -> Gemma | I8: =INDEX({"Gemma","Ministral","Qwen"},MATCH(LARGE(E8:G8,2),E8:G8,0)) -> Qwen | J8: =INDEX({"Gemma","Ministral","Qwen"},MATCH(LARGE(E8:G8,3),E8:G8,0)) -> Ministral | K8: =CORREL('03B_시나리오점수'!$K$5:$K$979,'03B_시나리오점수'!$N$5:$N$979) -> 0.98722101
A9: equal (1/3 each) | B9: 0.33333333 | C9: 0.33333333 | D9: 0.33333333 | E9: =AVERAGEIFS('03B_시나리오점수'!$I$5:$I$979,'01_원자료'!$C$2:$C$976,"gemma") -> 0.57983074 | F9: =AVERAGEIFS('03B_시나리오점수'!$I$5:$I$979,'01_원자료'!$C$2:$C$976,"ministral") -> 0.50088855 | G9: =AVERAGEIFS('03B_시나리오점수'!$I$5:$I$979,'01_원자료'!$C$2:$C$976,"qwen") -> 0.5857117 | H9: =INDEX({"Gemma","Ministral","Qwen"},MATCH(LARGE(E9:G9,1),E9:G9,0)) -> Qwen | I9: =INDEX({"Gemma","Ministral","Qwen"},MATCH(LARGE(E9:G9,2),E9:G9,0)) -> Gemma | J9: =INDEX({"Gemma","Ministral","Qwen"},MATCH(LARGE(E9:G9,3),E9:G9,0)) -> Ministral | K9: =CORREL('03B_시나리오점수'!$K$5:$K$979,'03B_시나리오점수'!$O$5:$O$979) -> 0.99476359
A10: sem_struct (0/50/50) | B10: 0 | C10: 0.5 | D10: 0.5 | E10: =AVERAGEIFS('03B_시나리오점수'!$J$5:$J$979,'01_원자료'!$C$2:$C$976,"gemma") -> 0.74854712 | F10: =AVERAGEIFS('03B_시나리오점수'!$J$5:$J$979,'01_원자료'!$C$2:$C$976,"ministral") -> 0.62952184 | G10: =AVERAGEIFS('03B_시나리오점수'!$J$5:$J$979,'01_원자료'!$C$2:$C$976,"qwen") -> 0.7230812 | H10: =INDEX({"Gemma","Ministral","Qwen"},MATCH(LARGE(E10:G10,1),E10:G10,0)) -> Gemma | I10: =INDEX({"Gemma","Ministral","Qwen"},MATCH(LARGE(E10:G10,2),E10:G10,0)) -> Qwen | J10: =INDEX({"Gemma","Ministral","Qwen"},MATCH(LARGE(E10:G10,3),E10:G10,0)) -> Ministral | K10: =CORREL('03B_시나리오점수'!$K$5:$K$979,'03B_시나리오점수'!$P$5:$P$979) -> 0.98969632
A12: Spearman rho 범위 | K12: =TEXT(MIN(K5:K10),"0.000")&" ~ "&TEXT(MAX(K5:K10),"0.000") -> 0.987 ~ 1.000
A14: 해석: 6개 시나리오 전부에서 Ministral이 최하위로 고정되고, baseline 대비 Spearman 순위 상관이 모두 0.98 이상이다. 즉 Overall Score의 결론은 가중치 선택에 강건하다.
A15: 단, Gemma와 Qwen의 1·2위 순서는 시나리오에 따라 뒤바뀐다(두 모델 평균 차이 0.003 미만). 따라서 논문은 두 모델의 순위를 해석하지 않는다.
A16: rho의 분석 단위는 975개 평가쌍의 점수다. 모델 3개의 순위만으로 Spearman을 계산하면 값이 1.0 또는 0.5만 가능하므로 민감도 지표로 쓸 수 없다.
A17: sem_struct 시나리오는 어휘 가중치가 0이므로 어휘 그룹을 완전히 배제한 극단 검증이다.

Sheet 03B_시나리오점수
A1: 가중치 시나리오별 평가쌍 점수와 순위 (03_가중치민감도 계산용)
A2: E~J열 = 각 시나리오의 975개 평가쌍 점수, K~P열 = 그 평균순위. Spearman rho = 순위끼리의 CORREL.
A4: document_id | B4: reference_model | C4: comparison_model | E4: 점수 baseline (20/45/35) | F4: 점수 lex_heavy (40/30/30) | G4: 점수 sem_heavy (20/50/30) | H4: 점수 struct_heavy (20/20/60) | I4: 점수 equal (1/3 each) | J4: 점수 sem_struct (0/50/50) | K4: 순위 baseline (20/45/35) | L4: 순위 lex_heavy (40/30/30) | M4: 순위 sem_heavy (20/50/30) | N4: 순위 struct_heavy (20/20/60) | O4: 순위 equal (1/3 each) | P4: 순위 sem_struct (0/50/50)
A5: ='01_원자료'!A2 -> PAT-01 | B5: ='01_원자료'!B2 -> chatgpt | C5: ='01_원자료'!C2 -> gemma | E5: ='01_원자료'!P2*'03_가중치민감도'!$B$5+'01_원자료'!Q2*'03_가중치민감도'!$C$5+'01_원자료'!R2*'03_가중치민감도'!$D$5 -> 0.52338109 | F5: ='01_원자료'!P2*'03_가중치민감도'!$B$6+'01_원자료'!Q2*'03_가중치민감도'!$C$6+'01_원자료'!R2*'03_가중치민감도'!$D$6 -> 0.44326375 | G5: ='01_원자료'!P2*'03_가중치민감도'!$B$7+'01_원자료'!Q2*'03_가중치민감도'!$C$7+'01_원자료'!R2*'03_가중치민감도'!$D$7 -> 0.5287118 | H5: ='01_원자료'!P2*'03_가중치민감도'!$B$8+'01_원자료'!Q2*'03_가중치민감도'!$C$8+'01_원자료'!R2*'03_가중치민감도'!$D$8 -> 0.49672754 | I5: ='01_원자료'!P2*'03_가중치민감도'!$B$9+'01_원자료'!Q2*'03_가중치민감도'!$C$9+'01_원자료'!R2*'03_가중치민감도'!$D$9 -> 0.46819263 | J5: ='01_원자료'!P2*'03_가중치민감도'!$B$10+'01_원자료'!Q2*'03_가중치민감도'!$C$10+'01_원자료'!R2*'03_가중치민감도'!$D$10 -> 0.59283702 | K5: =COUNTIF($E$5:$E$979,"<"&E5)+(COUNTIF($E$5:$E$979,"="&E5)+1)/2 -> 113 | L5: =COUNTIF($F$5:$F$979,"<"&F5)+(COUNTIF($F$5:$F$979,"="&F5)+1)/2 -> 109 | M5: =COUNTIF($G$5:$G$979,"<"&G5)+(COUNTIF($G$5:$G$979,"="&G5)+1)/2 -> 67 | N5: =COUNTIF($H$5:$H$979,"<"&H5)+(COUNTIF($H$5:$H$979,"="&H5)+1)/2 -> 219 | O5: =COUNTIF($I$5:$I$979,"<"&I5)+(COUNTIF($I$5:$I$979,"="&I5)+1)/2 -> 123 | P5: =COUNTIF($J$5:$J$979,"<"&J5)+(COUNTIF($J$5:$J$979,"="&J5)+1)/2 -> 164
A6: ='01_원자료'!A3 -> PAT-01 | B6: ='01_원자료'!B3 -> chatgpt | C6: ='01_원자료'!C3 -> ministral | E6: ='01_원자료'!P3*'03_가중치민감도'!$B$5+'01_원자료'!Q3*'03_가중치민감도'!$C$5+'01_원자료'!R3*'03_가중치민감도'!$D$5 -> 0.53773047 | F6: ='01_원자료'!P3*'03_가중치민감도'!$B$6+'01_원자료'!Q3*'03_가중치민감도'!$C$6+'01_원자료'!R3*'03_가중치민감도'!$D$6 -> 0.45705686 | G6: ='01_원자료'!P3*'03_가중치민감도'!$B$7+'01_원자료'!Q3*'03_가중치민감도'!$C$7+'01_원자료'!R3*'03_가중치민감도'!$D$7 -> 0.54834419 | H6: ='01_원자료'!P3*'03_가중치민감도'!$B$8+'01_원자료'!Q3*'03_가중치민감도'!$C$8+'01_원자료'!R3*'03_가중치민감도'!$D$8 -> 0.48466186 | I6: ='01_원자료'!P3*'03_가중치민감도'!$B$9+'01_원자료'!Q3*'03_가중치민감도'!$C$9+'01_원자료'!R3*'03_가중치민감도'!$D$9 -> 0.48041016 | J6: ='01_원자료'!P3*'03_가중치민감도'!$B$10+'01_원자료'!Q3*'03_가중치민감도'!$C$10+'01_원자료'!R3*'03_가중치민감도'!$D$10 -> 0.59717664 | K6: =COUNTIF($E$5:$E$979,"<"&E6)+(COUNTIF($E$5:$E$979,"="&E6)+1)/2 -> 161 | L6: =COUNTIF($F$5:$F$979,"<"&F6)+(COUNTIF($F$5:$F$979,"="&F6)+1)/2 -> 166 | M6: =COUNTIF($G$5:$G$979,"<"&G6)+(COUNTIF($G$5:$G$979,"="&G6)+1)/2 -> 147 | N6: =COUNTIF($H$5:$H$979,"<"&H6)+(COUNTIF($H$5:$H$979,"="&H6)+1)/2 -> 187 | O6: =COUNTIF($I$5:$I$979,"<"&I6)+(COUNTIF($I$5:$I$979,"="&I6)+1)/2 -> 167 | P6: =COUNTIF($J$5:$J$979,"<"&J6)+(COUNTIF($J$5:$J$979,"="&J6)+1)/2 -> 176
A7: ='01_원자료'!A4 -> PAT-01 | B7: ='01_원자료'!B4 -> chatgpt | C7: ='01_원자료'!C4 -> qwen | E7: ='01_원자료'!P4*'03_가중치민감도'!$B$5+'01_원자료'!Q4*'03_가중치민감도'!$C$5+'01_원자료'!R4*'03_가중치민감도'!$D$5 -> 0.50723802 | F7: ='01_원자료'!P4*'03_가중치민감도'!$B$6+'01_원자료'!Q4*'03_가중치민감도'!$C$6+'01_원자료'!R4*'03_가중치민감도'!$D$6 -> 0.44151577 | G7: ='01_원자료'!P4*'03_가중치민감도'!$B$7+'01_원자료'!Q4*'03_가중치민감도'!$C$7+'01_원자료'!R4*'03_가중치민감도'!$D$7 -> 0.51666562 | H7: ='01_원자료'!P4*'03_가중치민감도'!$B$8+'01_원자료'!Q4*'03_가중치민감도'!$C$8+'01_원자료'!R4*'03_가중치민감도'!$D$8 -> 0.46010001 | I7: ='01_원자료'!P4*'03_가중치민감도'!$B$9+'01_원자료'!Q4*'03_가중치민감도'!$C$9+'01_원자료'!R4*'03_가중치민감도'!$D$9 -> 0.46028065 | J7: ='01_원자료'!P4*'03_가중치민감도'!$B$10+'01_원자료'!Q4*'03_가중치민감도'!$C$10+'01_원자료'!R4*'03_가중치민감도'!$D$10 -> 0.55410507 | K7: =COUNTIF($E$5:$E$979,"<"&E7)+(COUNTIF($E$5:$E$979,"="&E7)+1)/2 -> 60 | L7: =COUNTIF($F$5:$F$979,"<"&F7)+(COUNTIF($F$5:$F$979,"="&F7)+1)/2 -> 102 | M7: =COUNTIF($G$5:$G$979,"<"&G7)+(COUNTIF($G$5:$G$979,"="&G7)+1)/2 -> 42 | N7: =COUNTIF($H$5:$H$979,"<"&H7)+(COUNTIF($H$5:$H$979,"="&H7)+1)/2 -> 147 | O7: =COUNTIF($I$5:$I$979,"<"&I7)+(COUNTIF($I$5:$I$979,"="&I7)+1)/2 -> 96 | P7: =COUNTIF($J$5:$J$979,"<"&J7)+(COUNTIF($J$5:$J$979,"="&J7)+1)/2 -> 73
A8: ='01_원자료'!A5 -> PAT-01 | B8: ='01_원자료'!B5 -> claude | C8: ='01_원자료'!C5 -> gemma | E8: ='01_원자료'!P5*'03_가중치민감도'!$B$5+'01_원자료'!Q5*'03_가중치민감도'!$C$5+'01_원자료'!R5*'03_가중치민감도'!$D$5 -> 0.61235739 | F8: ='01_원자료'!P5*'03_가중치민감도'!$B$6+'01_원자료'!Q5*'03_가중치민감도'!$C$6+'01_원자료'!R5*'03_가중치민감도'!$D$6 -> 0.5121068 | G8: ='01_원자료'!P5*'03_가중치민감도'!$B$7+'01_원자료'!Q5*'03_가중치민감도'!$C$7+'01_원자료'!R5*'03_가중치민감도'!$D$7 -> 0.61373167 | H8: ='01_원자료'!P5*'03_가중치민감도'!$B$8+'01_원자료'!Q5*'03_가중치민감도'!$C$8+'01_원자료'!R5*'03_가중치민감도'!$D$8 -> 0.60548598 | I8: ='01_원자료'!P5*'03_가중치민감도'!$B$9+'01_원자료'!Q5*'03_가중치민감도'!$C$9+'01_원자료'!R5*'03_가중치민감도'!$D$9 -> 0.54506557 | J8: ='01_원자료'!P5*'03_가중치민감도'!$B$10+'01_원자료'!Q5*'03_가중치민감도'!$C$10+'01_원자료'!R5*'03_가중치민감도'!$D$10 -> 0.70985942 | K8: =COUNTIF($E$5:$E$979,"<"&E8)+(COUNTIF($E$5:$E$979,"="&E8)+1)/2 -> 448 | L8: =COUNTIF($F$5:$F$979,"<"&F8)+(COUNTIF($F$5:$F$979,"="&F8)+1)/2 -> 422 | M8: =COUNTIF($G$5:$G$979,"<"&G8)+(COUNTIF($G$5:$G$979,"="&G8)+1)/2 -> 426 | N8: =COUNTIF($H$5:$H$979,"<"&H8)+(COUNTIF($H$5:$H$979,"="&H8)+1)/2 -> 507 | O8: =COUNTIF($I$5:$I$979,"<"&I8)+(COUNTIF($I$5:$I$979,"="&I8)+1)/2 -> 436 | P8: =COUNTIF($J$5:$J$979,"<"&J8)+(COUNTIF($J$5:$J$979,"="&J8)+1)/2 -> 497
A9: ='01_원자료'!A6 -> PAT-01 | B9: ='01_원자료'!B6 -> claude | C9: ='01_원자료'!C6 -> ministral | E9: ='01_원자료'!P6*'03_가중치민감도'!$B$5+'01_원자료'!Q6*'03_가중치민감도'!$C$5+'01_원자료'!R6*'03_가중치민감도'!$D$5 -> 0.60963526 | F9: ='01_원자료'!P6*'03_가중치민감도'!$B$6+'01_원자료'!Q6*'03_가중치민감도'!$C$6+'01_원자료'!R6*'03_가중치민감도'!$D$6 -> 0.50583565 | G9: ='01_원자료'!P6*'03_가중치민감도'!$B$7+'01_원자료'!Q6*'03_가중치민감도'!$C$7+'01_원자료'!R6*'03_가중치민감도'!$D$7 -> 0.61193267 | H9: ='01_원자료'!P6*'03_가중치민감도'!$B$8+'01_원자료'!Q6*'03_가중치민감도'!$C$8+'01_원자료'!R6*'03_가중치민감도'!$D$8 -> 0.59814819 | I9: ='01_원자료'!P6*'03_가중치민감도'!$B$9+'01_원자료'!Q6*'03_가중치민감도'!$C$9+'01_원자료'!R6*'03_가중치민감도'!$D$9 -> 0.53966971 | J9: ='01_원자료'!P6*'03_가중치민감도'!$B$10+'01_원자료'!Q6*'03_가중치민감도'!$C$10+'01_원자료'!R6*'03_가중치민감도'!$D$10 -> 0.70884004 | K9: =COUNTIF($E$5:$E$979,"<"&E9)+(COUNTIF($E$5:$E$979,"="&E9)+1)/2 -> 428 | L9: =COUNTIF($F$5:$F$979,"<"&F9)+(COUNTIF($F$5:$F$979,"="&F9)+1)/2 -> 394 | M9: =COUNTIF($G$5:$G$979,"<"&G9)+(COUNTIF($G$5:$G$979,"="&G9)+1)/2 -> 419 | N9: =COUNTIF($H$5:$H$979,"<"&H9)+(COUNTIF($H$5:$H$979,"="&H9)+1)/2 -> 482 | O9: =COUNTIF($I$5:$I$979,"<"&I9)+(COUNTIF($I$5:$I$979,"="&I9)+1)/2 -> 412 | P9: =COUNTIF($J$5:$J$979,"<"&J9)+(COUNTIF($J$5:$J$979,"="&J9)+1)/2 -> 491
A10: ='01_원자료'!A7 -> PAT-01 | B10: ='01_원자료'!B7 -> claude | C10: ='01_원자료'!C7 -> qwen | E10: ='01_원자료'!P7*'03_가중치민감도'!$B$5+'01_원자료'!Q7*'03_가중치민감도'!$C$5+'01_원자료'!R7*'03_가중치민감도'!$D$5 -> 0.62760022 | F10: ='01_원자료'!P7*'03_가중치민감도'!$B$6+'01_원자료'!Q7*'03_가중치민감도'!$C$6+'01_원자료'!R7*'03_가중치민감도'!$D$6 -> 0.53572412 | G10: ='01_원자료'!P7*'03_가중치민감도'!$B$7+'01_원자료'!Q7*'03_가중치민감도'!$C$7+'01_원자료'!R7*'03_가중치민감도'!$D$7 -> 0.62743424 | H10: ='01_원자료'!P7*'03_가중치민감도'!$B$8+'01_원자료'!Q7*'03_가중치민감도'!$C$8+'01_원자료'!R7*'03_가중치민감도'!$D$8 -> 0.62843012 | I10: ='01_원자료'!P7*'03_가중치민감도'!$B$9+'01_원자료'!Q7*'03_가중치민감도'!$C$9+'01_원자료'!R7*'03_가중치민감도'!$D$9 -> 0.56640481 | J10: ='01_원자료'!P7*'03_가중치민감도'!$B$10+'01_원자료'!Q7*'03_가중치민감도'!$C$10+'01_원자료'!R7*'03_가중치민감도'!$D$10 -> 0.71980827 | K10: =COUNTIF($E$5:$E$979,"<"&E10)+(COUNTIF($E$5:$E$979,"="&E10)+1)/2 -> 519 | L10: =COUNTIF($F$5:$F$979,"<"&F10)+(COUNTIF($F$5:$F$979,"="&F10)+1)/2 -> 527 | M10: =COUNTIF($G$5:$G$979,"<"&G10)+(COUNTIF($G$5:$G$979,"="&G10)+1)/2 -> 502 | N10: =COUNTIF($H$5:$H$979,"<"&H10)+(COUNTIF($H$5:$H$979,"="&H10)+1)/2 -> 572 | O10: =COUNTIF($I$5:$I$979,"<"&I10)+(COUNTIF($I$5:$I$979,"="&I10)+1)/2 -> 532 | P10: =COUNTIF($J$5:$J$979,"<"&J10)+(COUNTIF($J$5:$J$979,"="&J10)+1)/2 -> 545
A11: ='01_원자료'!A8 -> PAT-01 | B11: ='01_원자료'!B8 -> gemini | C11: ='01_원자료'!C8 -> gemma | E11: ='01_원자료'!P8*'03_가중치민감도'!$B$5+'01_원자료'!Q8*'03_가중치민감도'!$C$5+'01_원자료'!R8*'03_가중치민감도'!$D$5 -> 0.71977399 | F11: ='01_원자료'!P8*'03_가중치민감도'!$B$6+'01_원자료'!Q8*'03_가중치민감도'!$C$6+'01_원자료'!R8*'03_가중치민감도'!$D$6 -> 0.60379483 | G11: ='01_원자료'!P8*'03_가중치민감도'!$B$7+'01_원자료'!Q8*'03_가중치민감도'!$C$7+'01_원자료'!R8*'03_가중치민감도'!$D$7 -> 0.71099762 | H11: ='01_원자료'!P8*'03_가중치민감도'!$B$8+'01_원자료'!Q8*'03_가중치민감도'!$C$8+'01_원자료'!R8*'03_가중치민감도'!$D$8 -> 0.76365583 | I11: ='01_원자료'!P8*'03_가중치민감도'!$B$9+'01_원자료'!Q8*'03_가중치민감도'!$C$9+'01_원자료'!R8*'03_가중치민감도'!$D$9 -> 0.64538 | J11: ='01_원자료'!P8*'03_가중치민감도'!$B$10+'01_원자료'!Q8*'03_가중치민감도'!$C$10+'01_원자료'!R8*'03_가중치민감도'!$D$10 -> 0.85330588 | K11: =COUNTIF($E$5:$E$979,"<"&E11)+(COUNTIF($E$5:$E$979,"="&E11)+1)/2 -> 878 | L11: =COUNTIF($F$5:$F$979,"<"&F11)+(COUNTIF($F$5:$F$979,"="&F11)+1)/2 -> 827 | M11: =COUNTIF($G$5:$G$979,"<"&G11)+(COUNTIF($G$5:$G$979,"="&G11)+1)/2 -> 875 | N11: =COUNTIF($H$5:$H$979,"<"&H11)+(COUNTIF($H$5:$H$979,"="&H11)+1)/2 -> 877 | O11: =COUNTIF($I$5:$I$979,"<"&I11)+(COUNTIF($I$5:$I$979,"="&I11)+1)/2 -> 852 | P11: =COUNTIF($J$5:$J$979,"<"&J11)+(COUNTIF($J$5:$J$979,"="&J11)+1)/2 -> 898
A12: ='01_원자료'!A9 -> PAT-01 | B12: ='01_원자료'!B9 -> gemini | C12: ='01_원자료'!C9 -> ministral | E12: ='01_원자료'!P9*'03_가중치민감도'!$B$5+'01_원자료'!Q9*'03_가중치민감도'!$C$5+'01_원자료'!R9*'03_가중치민감도'!$D$5 -> 0.60410725 | F12: ='01_원자료'!P9*'03_가중치민감도'!$B$6+'01_원자료'!Q9*'03_가중치민감도'!$C$6+'01_원자료'!R9*'03_가중치민감도'!$D$6 -> 0.49570782 | G12: ='01_원자료'!P9*'03_가중치민감도'!$B$7+'01_원자료'!Q9*'03_가중치민감도'!$C$7+'01_원자료'!R9*'03_가중치민감도'!$D$7 -> 0.61420428 | H12: ='01_원자료'!P9*'03_가중치민감도'!$B$8+'01_원자료'!Q9*'03_가중치민감도'!$C$8+'01_원자료'!R9*'03_가중치민감도'!$D$8 -> 0.55362208 | I12: ='01_원자료'!P9*'03_가중치민감도'!$B$9+'01_원자료'!Q9*'03_가중치민감도'!$C$9+'01_원자료'!R9*'03_가중치민감도'!$D$9 -> 0.52847528 | J12: ='01_원자료'!P9*'03_가중치민감도'!$B$10+'01_원자료'!Q9*'03_가중치민감도'!$C$10+'01_원자료'!R9*'03_가중치민감도'!$D$10 -> 0.69231261 | K12: =COUNTIF($E$5:$E$979,"<"&E12)+(COUNTIF($E$5:$E$979,"="&E12)+1)/2 -> 408 | L12: =COUNTIF($F$5:$F$979,"<"&F12)+(COUNTIF($F$5:$F$979,"="&F12)+1)/2 -> 338 | M12: =COUNTIF($G$5:$G$979,"<"&G12)+(COUNTIF($G$5:$G$979,"="&G12)+1)/2 -> 431 | N12: =COUNTIF($H$5:$H$979,"<"&H12)+(COUNTIF($H$5:$H$979,"="&H12)+1)/2 -> 350 | O12: =COUNTIF($I$5:$I$979,"<"&I12)+(COUNTIF($I$5:$I$979,"="&I12)+1)/2 -> 363 | P12: =COUNTIF($J$5:$J$979,"<"&J12)+(COUNTIF($J$5:$J$979,"="&J12)+1)/2 -> 431
A13: ='01_원자료'!A10 -> PAT-01 | B13: ='01_원자료'!B10 -> gemini | C13: ='01_원자료'!C10 -> qwen | E13: ='01_원자료'!P10*'03_가중치민감도'!$B$5+'01_원자료'!Q10*'03_가중치민감도'!$C$5+'01_원자료'!R10*'03_가중치민감도'!$D$5 -> 0.64461104 | F13: ='01_원자료'!P10*'03_가중치민감도'!$B$6+'01_원자료'!Q10*'03_가중치민감도'!$C$6+'01_원자료'!R10*'03_가중치민감도'!$D$6 -> 0.54521349 | G13: ='01_원자료'!P10*'03_가중치민감도'!$B$7+'01_원자료'!Q10*'03_가중치민감도'!$C$7+'01_원자료'!R10*'03_가중치민감도'!$D$7 -> 0.6479123 | H13: ='01_원자료'!P10*'03_가중치민감도'!$B$8+'01_원자료'!Q10*'03_가중치민감도'!$C$8+'01_원자료'!R10*'03_가중치민감도'!$D$8 -> 0.62810471 | I13: ='01_원자료'!P10*'03_가중치민감도'!$B$9+'01_원자료'!Q10*'03_가중치민감도'!$C$9+'01_원자료'!R10*'03_가중치민감도'!$D$9 -> 0.57724558 | J13: ='01_원자료'!P10*'03_가중치민감도'!$B$10+'01_원자료'!Q10*'03_가중치민감도'!$C$10+'01_원자료'!R10*'03_가중치민감도'!$D$10 -> 0.73740605 | K13: =COUNTIF($E$5:$E$979,"<"&E13)+(COUNTIF($E$5:$E$979,"="&E13)+1)/2 -> 595 | L13: =COUNTIF($F$5:$F$979,"<"&F13)+(COUNTIF($F$5:$F$979,"="&F13)+1)/2 -> 560 | M13: =COUNTIF($G$5:$G$979,"<"&G13)+(COUNTIF($G$5:$G$979,"="&G13)+1)/2 -> 606 | N13: =COUNTIF($H$5:$H$979,"<"&H13)+(COUNTIF($H$5:$H$979,"="&H13)+1)/2 -> 570 | O13: =COUNTIF($I$5:$I$979,"<"&I13)+(COUNTIF($I$5:$I$979,"="&I13)+1)/2 -> 578 | P13: =COUNTIF($J$5:$J$979,"<"&J13)+(COUNTIF($J$5:$J$979,"="&J13)+1)/2 -> 612
A14: ='01_원자료'!A11 -> PAT-01 | B14: ='01_원자료'!B11 -> mistral | C14: ='01_원자료'!C11 -> gemma | E14: ='01_원자료'!P11*'03_가중치민감도'!$B$5+'01_원자료'!Q11*'03_가중치민감도'!$C$5+'01_원자료'!R11*'03_가중치민감도'!$D$5 -> 0.56918695 | F14: ='01_원자료'!P11*'03_가중치민감도'!$B$6+'01_원자료'!Q11*'03_가중치민감도'!$C$6+'01_원자료'!R11*'03_가중치민감도'!$D$6 -> 0.48051013 | G14: ='01_원자료'!P11*'03_가중치민감도'!$B$7+'01_원자료'!Q11*'03_가중치민감도'!$C$7+'01_원자료'!R11*'03_가중치민감도'!$D$7 -> 0.56989346 | H14: ='01_원자료'!P11*'03_가중치민감도'!$B$8+'01_원자료'!Q11*'03_가중치민감도'!$C$8+'01_원자료'!R11*'03_가중치민감도'!$D$8 -> 0.56565444 | I14: ='01_원자료'!P11*'03_가중치민감도'!$B$9+'01_원자료'!Q11*'03_가중치민감도'!$C$9+'01_원자료'!R11*'03_가중치민감도'!$D$9 -> 0.50983357 | J14: ='01_원자료'!P11*'03_가중치민감도'!$B$10+'01_원자료'!Q11*'03_가중치민감도'!$C$10+'01_원자료'!R11*'03_가중치민감도'!$D$10 -> 0.65645078 | K14: =COUNTIF($E$5:$E$979,"<"&E14)+(COUNTIF($E$5:$E$979,"="&E14)+1)/2 -> 281 | L14: =COUNTIF($F$5:$F$979,"<"&F14)+(COUNTIF($F$5:$F$979,"="&F14)+1)/2 -> 269 | M14: =COUNTIF($G$5:$G$979,"<"&G14)+(COUNTIF($G$5:$G$979,"="&G14)+1)/2 -> 245 | N14: =COUNTIF($H$5:$H$979,"<"&H14)+(COUNTIF($H$5:$H$979,"="&H14)+1)/2 -> 386 | O14: =COUNTIF($I$5:$I$979,"<"&I14)+(COUNTIF($I$5:$I$979,"="&I14)+1)/2 -> 287 | P14: =COUNTIF($J$5:$J$979,"<"&J14)+(COUNTIF($J$5:$J$979,"="&J14)+1)/2 -> 323
A15: ='01_원자료'!A12 -> PAT-01 | B15: ='01_원자료'!B12 -> mistral | C15: ='01_원자료'!C12 -> ministral | E15: ='01_원자료'!P12*'03_가중치민감도'!$B$5+'01_원자료'!Q12*'03_가중치민감도'!$C$5+'01_원자료'!R12*'03_가중치민감도'!$D$5 -> 0.63476998 | F15: ='01_원자료'!P12*'03_가중치민감도'!$B$6+'01_원자료'!Q12*'03_가중치민감도'!$C$6+'01_원자료'!R12*'03_가중치민감도'!$D$6 -> 0.54632473 | G15: ='01_원자료'!P12*'03_가중치민감도'!$B$7+'01_원자료'!Q12*'03_가중치민감도'!$C$7+'01_원자료'!R12*'03_가중치민감도'!$D$7 -> 0.63357348 | H15: ='01_원자료'!P12*'03_가중치민감도'!$B$8+'01_원자료'!Q12*'03_가중치민감도'!$C$8+'01_원자료'!R12*'03_가중치민감도'!$D$8 -> 0.6407525 | I15: ='01_원자료'!P12*'03_가중치민감도'!$B$9+'01_원자료'!Q12*'03_가중치민감도'!$C$9+'01_원자료'!R12*'03_가중치민감도'!$D$9 -> 0.57620531 | J15: ='01_원자료'!P12*'03_가중치민감도'!$B$10+'01_원자료'!Q12*'03_가중치민감도'!$C$10+'01_원자료'!R12*'03_가중치민감도'!$D$10 -> 0.72560824 | K15: =COUNTIF($E$5:$E$979,"<"&E15)+(COUNTIF($E$5:$E$979,"="&E15)+1)/2 -> 552 | L15: =COUNTIF($F$5:$F$979,"<"&F15)+(COUNTIF($F$5:$F$979,"="&F15)+1)/2 -> 569 | M15: =COUNTIF($G$5:$G$979,"<"&G15)+(COUNTIF($G$5:$G$979,"="&G15)+1)/2 -> 531 | N15: =COUNTIF($H$5:$H$979,"<"&H15)+(COUNTIF($H$5:$H$979,"="&H15)+1)/2 -> 609 | O15: =COUNTIF($I$5:$I$979,"<"&I15)+(COUNTIF($I$5:$I$979,"="&I15)+1)/2 -> 572 | P15: =COUNTIF($J$5:$J$979,"<"&J15)+(COUNTIF($J$5:$J$979,"="&J15)+1)/2 -> 567
A16: ='01_원자료'!A13 -> PAT-01 | B16: ='01_원자료'!B13 -> mistral | C16: ='01_원자료'!C13 -> qwen | E16: ='01_원자료'!P13*'03_가중치민감도'!$B$5+'01_원자료'!Q13*'03_가중치민감도'!$C$5+'01_원자료'!R13*'03_가중치민감도'!$D$5 -> 0.66727538 | F16: ='01_원자료'!P13*'03_가중치민감도'!$B$6+'01_원자료'!Q13*'03_가중치민감도'!$C$6+'01_원자료'!R13*'03_가중치민감도'!$D$6 -> 0.58213472 | G16: ='01_원자료'!P13*'03_가중치민감도'!$B$7+'01_원자료'!Q13*'03_가중치민감도'!$C$7+'01_원자료'!R13*'03_가중치민감도'!$D$7 -> 0.65765211 | H16: ='01_원자료'!P13*'03_가중치민감도'!$B$8+'01_원자료'!Q13*'03_가중치민감도'!$C$8+'01_원자료'!R13*'03_가중치민감도'!$D$8 -> 0.71539168 | I16: ='01_원자료'!P13*'03_가중치민감도'!$B$9+'01_원자료'!Q13*'03_가중치민감도'!$C$9+'01_원자료'!R13*'03_가중치민감도'!$D$9 -> 0.61372269 | J16: ='01_원자료'!P13*'03_가중치민감도'!$B$10+'01_원자료'!Q13*'03_가중치민감도'!$C$10+'01_원자료'!R13*'03_가중치민감도'!$D$10 -> 0.77166255 | K16: =COUNTIF($E$5:$E$979,"<"&E16)+(COUNTIF($E$5:$E$979,"="&E16)+1)/2 -> 704 | L16: =COUNTIF($F$5:$F$979,"<"&F16)+(COUNTIF($F$5:$F$979,"="&F16)+1)/2 -> 745 | M16: =COUNTIF($G$5:$G$979,"<"&G16)+(COUNTIF($G$5:$G$979,"="&G16)+1)/2 -> 652 | N16: =COUNTIF($H$5:$H$979,"<"&H16)+(COUNTIF($H$5:$H$979,"="&H16)+1)/2 -> 820 | O16: =COUNTIF($I$5:$I$979,"<"&I16)+(COUNTIF($I$5:$I$979,"="&I16)+1)/2 -> 743 | P16: =COUNTIF($J$5:$J$979,"<"&J16)+(COUNTIF($J$5:$J$979,"="&J16)+1)/2 -> 724
... A979: ='01_원자료'!A976 -> RPT-34 | B979: ='01_원자료'!B976 -> qwen3_6 | C979: ='01_원자료'!C976 -> qwen | E979: ='01_원자료'!P976*'03_가중치민감도'!$B$5+'01_원자료'!Q976*'03_가중치민감도'!$C$5+'01_원자료'!R976*'03_가중치민감도'!$D$5 -> 0.71819111 | F979: ='01_원자료'!P976*'03_가중치민감도'!$B$6+'01_원자료'!Q976*'03_가중치민감도'!$C$6+'01_원자료'!R976*'03_가중치민감도'!$D$6 -> 0.6207494 | G979: ='01_원자료'!P976*'03_가중치민감도'!$B$7+'01_원자료'!Q976*'03_가중치민감도'!$C$7+'01_원자료'!R976*'03_가중치민감도'!$D$7 -> 0.70773804 | H979: ='01_원자료'!P976*'03_가중치민감도'!$B$8+'01_원자료'!Q976*'03_가중치민감도'!$C$8+'01_원자료'!R976*'03_가중치민감도'!$D$8 -> 0.77045642 | I979: ='01_원자료'!P976*'03_가중치민감도'!$B$9+'01_원자료'!Q976*'03_가중치민감도'!$C$9+'01_원자료'!R976*'03_가중치민감도'!$D$9 -> 0.65671432 | J979: ='01_원자료'!P976*'03_가중치민감도'!$B$10+'01_원자료'!Q976*'03_가중치민감도'!$C$10+'01_원자료'!R976*'03_가중치민감도'!$D$10 -> 0.83653894 | K979: =COUNTIF($E$5:$E$979,"<"&E979)+(COUNTIF($E$5:$E$979,"="&E979)+1)/2 -> 871 | L979: =COUNTIF($F$5:$F$979,"<"&F979)+(COUNTIF($F$5:$F$979,"="&F979)+1)/2 -> 898 | M979: =COUNTIF($G$5:$G$979,"<"&G979)+(COUNTIF($G$5:$G$979,"="&G979)+1)/2 -> 859 | N979: =COUNTIF($H$5:$H$979,"<"&H979)+(COUNTIF($H$5:$H$979,"="&H979)+1)/2 -> 902 | O979: =COUNTIF($I$5:$I$979,"<"&I979)+(COUNTIF($I$5:$I$979,"="&I979)+1)/2 -> 895 | P979: =COUNTIF($J$5:$J$979,"<"&J979)+(COUNTIF($J$5:$J$979,"="&J979)+1)/2 -> 855

Sheet 04_교차표
A1: 레퍼런스 x 모델 교차표 (Overall Score 셀 평균)
A2: 각 셀 = 문서 65건 평균. 이 표가 이원분산분석·계열편향 분석의 공통 입력이다.
A4: reference_model | B4: gemma | C4: ministral | D4: qwen | E4: 행평균(관대함) | F4: 표시명
A5: chatgpt | B5: =AVERAGEIFS('01_원자료'!$S$2:$S$976,'01_원자료'!$B$2:$B$976,$A5,'01_원자료'!$C$2:$C$976,B$4) -> 0.55255117 | C5: =AVERAGEIFS('01_원자료'!$S$2:$S$976,'01_원자료'!$B$2:$B$976,$A5,'01_원자료'!$C$2:$C$976,C$4) -> 0.52754903 | D5: =AVERAGEIFS('01_원자료'!$S$2:$S$976,'01_원자료'!$B$2:$B$976,$A5,'01_원자료'!$C$2:$C$976,D$4) -> 0.55645248 | E5: =AVERAGEIFS('01_원자료'!$S$2:$S$976,'01_원자료'!$B$2:$B$976,$A5) -> 0.54551756 | F5: ChatGPT
A6: claude | B6: =AVERAGEIFS('01_원자료'!$S$2:$S$976,'01_원자료'!$B$2:$B$976,$A6,'01_원자료'!$C$2:$C$976,B$4) -> 0.6313027 | C6: =AVERAGEIFS('01_원자료'!$S$2:$S$976,'01_원자료'!$B$2:$B$976,$A6,'01_원자료'!$C$2:$C$976,C$4) -> 0.57489078 | D6: =AVERAGEIFS('01_원자료'!$S$2:$S$976,'01_원자료'!$B$2:$B$976,$A6,'01_원자료'!$C$2:$C$976,D$4) -> 0.65842301 | E6: =AVERAGEIFS('01_원자료'!$S$2:$S$976,'01_원자료'!$B$2:$B$976,$A6) -> 0.62153883 | F6: Claude
A7: gemini | B7: =AVERAGEIFS('01_원자료'!$S$2:$S$976,'01_원자료'!$B$2:$B$976,$A7,'01_원자료'!$C$2:$C$976,B$4) -> 0.71765179 | C7: =AVERAGEIFS('01_원자료'!$S$2:$S$976,'01_원자료'!$B$2:$B$976,$A7,'01_원자료'!$C$2:$C$976,C$4) -> 0.57939907 | D7: =AVERAGEIFS('01_원자료'!$S$2:$S$976,'01_원자료'!$B$2:$B$976,$A7,'01_원자료'!$C$2:$C$976,D$4) -> 0.68823698 | E7: =AVERAGEIFS('01_원자료'!$S$2:$S$976,'01_원자료'!$B$2:$B$976,$A7) -> 0.66176261 | F7: Gemini
A8: mistral | B8: =AVERAGEIFS('01_원자료'!$S$2:$S$976,'01_원자료'!$B$2:$B$976,$A8,'01_원자료'!$C$2:$C$976,B$4) -> 0.62288162 | C8: =AVERAGEIFS('01_원자료'!$S$2:$S$976,'01_원자료'!$B$2:$B$976,$A8,'01_원자료'!$C$2:$C$976,C$4) -> 0.58122328 | D8: =AVERAGEIFS('01_원자료'!$S$2:$S$976,'01_원자료'!$B$2:$B$976,$A8,'01_원자료'!$C$2:$C$976,D$4) -> 0.63138887 | E8: =AVERAGEIFS('01_원자료'!$S$2:$S$976,'01_원자료'!$B$2:$B$976,$A8) -> 0.61183125 | F8: Mistral
A9: qwen3_6 | B9: =AVERAGEIFS('01_원자료'!$S$2:$S$976,'01_원자료'!$B$2:$B$976,$A9,'01_원자료'!$C$2:$C$976,B$4) -> 0.70798545 | C9: =AVERAGEIFS('01_원자료'!$S$2:$S$976,'01_원자료'!$B$2:$B$976,$A9,'01_원자료'!$C$2:$C$976,C$4) -> 0.55987161 | D9: =AVERAGEIFS('01_원자료'!$S$2:$S$976,'01_원자료'!$B$2:$B$976,$A9,'01_원자료'!$C$2:$C$976,D$4) -> 0.68241873 | E9: =AVERAGEIFS('01_원자료'!$S$2:$S$976,'01_원자료'!$B$2:$B$976,$A9) -> 0.65009193 | F9: Qwen3.6
A10: 열평균(모델) | B10: =AVERAGEIFS('01_원자료'!$S$2:$S$976,'01_원자료'!$C$2:$C$976,B$4) -> 0.64647455 | C10: =AVERAGEIFS('01_원자료'!$S$2:$S$976,'01_원자료'!$C$2:$C$976,C$4) -> 0.56458675 | D10: =AVERAGEIFS('01_원자료'!$S$2:$S$976,'01_원자료'!$C$2:$C$976,D$4) -> 0.64338401 | E10: =AVERAGE('01_원자료'!$S$2:$S$976) -> 0.61814844 | F10: ← 총평균 G
A11: 셀당 관측수 n | B11: =COUNTIFS('01_원자료'!$B$2:$B$976,$A$5,'01_원자료'!$C$2:$C$976,B$4) -> 65 | C11: =COUNTIFS('01_원자료'!$B$2:$B$976,$A$5,'01_원자료'!$C$2:$C$976,C$4) -> 65 | D11: =COUNTIFS('01_원자료'!$B$2:$B$976,$A$5,'01_원자료'!$C$2:$C$976,D$4) -> 65
A13: 이중 중심화 잔차 D* = (셀) - (행평균) - (열평균) + (총평균)
A14: 레퍼런스의 관대함과 모델의 실력을 동시에 제거한, 조합 고유의 상호작용 성분이다.
A15: reference_model | B15: gemma | C15: ministral | D15: qwen
A16: chatgpt | B16: =B5-$E5-B$10+$E$10 -> -0.021292504 | C16: =C5-$E5-C$10+$E$10 -> 0.035593156 | D16: =D5-$E5-D$10+$E$10 -> -0.014300652
A17: claude | B17: =B6-$E6-B$10+$E$10 -> -0.018562235 | C17: =C6-$E6-C$10+$E$10 -> 0.0069136315 | D17: =D6-$E6-D$10+$E$10 -> 0.011648603
A18: gemini | B18: =B7-$E7-B$10+$E$10 -> 0.027563069 | C18: =C7-$E7-C$10+$E$10 -> -0.028801855 | D18: =D7-$E7-D$10+$E$10 -> 0.0012387858
A19: mistral | B19: =B8-$E8-B$10+$E$10 -> -0.017275742 | C19: =C8-$E8-C$10+$E$10 -> 0.022953706 | D19: =D8-$E8-D$10+$E$10 -> -0.0056779639
A20: qwen3_6 | B20: =B9-$E9-B$10+$E$10 -> 0.029567412 | C20: =C9-$E9-C$10+$E$10 -> -0.036658638 | D20: =D9-$E9-D$10+$E$10 -> 0.0070912269
A21: 합계(검산) | B21: =SUM(B16:B20) -> 1.4432899e-15 | C21: =SUM(C16:C20) -> 7.7715612e-16 | D21: =SUM(D16:D20) -> -2.6645353e-15
A22: 검산: 이중 중심화 잔차는 행 방향·열 방향 합이 모두 0이 되어야 한다.

Sheet 05_이원분산분석
A1: 이원분산분석: 레퍼런스 효과 / 모델 효과 / 상호작용 (논문 4.2)
A2: 평방합 분해로 Overall Score 총변동을 세 요인에 배분한다. 설계: 레퍼런스 5 x 모델 3 x 문서 65 = 975 (균형설계)
A4: 기본량
A6: N (총 관측수) | B6: =COUNT('01_원자료'!$S$2:$S$976) -> 975
A7: a (레퍼런스 수준수) | B7: =COUNTA('04_교차표'!A5:A9) -> 5
A8: b (모델 수준수) | B8: =COUNTA('04_교차표'!B4:D4) -> 3
A9: r (셀당 반복수 = 문서 수) | B9: ='04_교차표'!B11 -> 65
A10: G (총평균) | B10: ='04_교차표'!E10 -> 0.61814844
A11: 평방합 분해
A12: 요인 | B12: 평방합 SS | C12: 산식 | D12: 자유도 df | E12: 평균제곱 MS | F12: F | G12: p | H12: eta squared
A13: 레퍼런스 (A) | B13: =$B$8*$B$9*SUMPRODUCT(('04_교차표'!E5:E9-$B$10)^2) -> 1.6085997 | C13: SS_A = b·r·Σ_i (행평균_i − G)² | D13: =$B$7-1 -> 4 | E13: =B13/D13 -> 0.40214992 | F13: =E13/$E$16 -> 173.56143 | G13: =FDIST(F13,D13,$D$16) -> 7.3873643e-112 | H13: =B13/$B$17 -> 0.28225489
A14: 모델 (B) | B14: =$B$7*$B$9*SUMPRODUCT(('04_교차표'!B10:D10-$B$10)^2) -> 1.4001185 | C14: SS_B = a·r·Σ_j (열평균_j − G)² | D14: =$B$8-1 -> 2 | E14: =B14/D14 -> 0.70005923 | F14: =E14/$E$16 -> 302.13429 | G14: =FDIST(F14,D14,$D$16) -> 1.6624878e-102 | H14: =B14/$B$17 -> 0.24567349
A15: 상호작용 (AxB) | B15: =$B$9*SUMPRODUCT('04_교차표'!B16:D20,'04_교차표'!B16:D20) -> 0.46601994 | C15: SS_AB = r·Σ_ij (셀_ij − 행_i − 열_j + G)² ← 04_교차표 B16:D20 | D15: =($B$7-1)*($B$8-1) -> 8 | E15: =B15/D15 -> 0.058252492 | F15: =E15/$E$16 -> 25.140837 | G15: =FDIST(F15,D15,$D$16) -> 2.2270403e-35 | H15: =B15/$B$17 -> 0.081770755
A16: 오차 (잔차) | B16: =B17-B13-B14-B15 -> 2.2243648 | C16: SS_E = SS_T − SS_A − SS_B − SS_AB | D16: =$B$6-$B$7*$B$8 -> 960 | E16: =B16/D16 -> 0.0023170466
A17: 총변동 | B17: =SUMPRODUCT(('01_원자료'!$S$2:$S$976-$B$10)^2) -> 5.6991028 | C17: SS_T = Σ (y − G)² | D17: =$B$6-1 -> 974
A19: 결과 요약
A20: eta² 레퍼런스 | B20: =H13 -> 0.28225489 | C20: 기준을 바꿀 때 점수가 이동하는 정도
A21: eta² 모델 | B21: =H14 -> 0.24567349 | C21: 피평가 모델을 바꿀 때 점수가 이동하는 정도
A22: eta² 상호작용 | B22: =H15 -> 0.081770755 | C22: 특정 레퍼런스-모델 조합에서만 나타나는 고유 효과
A23: 레퍼런스 관련 합 (A+AxB) | B23: =H13+H15 -> 0.36402565
A24: eta² 비 (레퍼런스/모델) | B24: =B20/B21 -> 1.1489026 | C24: 단일 요인끼리의 분산 배분 비교 (논문 본문의 "1.15배")
A25: 레퍼런스 주변평균 범위 | B25: =MAX('04_교차표'!E5:E9)-MIN('04_교차표'!E5:E9) -> 0.11624505 | C25: 가장 관대한 레퍼런스 − 가장 박한 레퍼런스
A26: 모델 주변평균 범위 | B26: =MAX('04_교차표'!B10:D10)-MIN('04_교차표'!B10:D10) -> 0.081887794 | C26: 최고 성능 모델 − 최저 성능 모델
A27: 점수 이동 비 (레퍼런스/모델) | B27: =B25/B26 -> 1.4195651 | C27: 기준을 바꿀 때의 점수 이동이 대상을 바꿀 때보다 몇 배 큰가 (논문 본문의 "약 1.4배")
A29: eta²의 의미: 총변동 100 중 해당 요인이 설명하는 몫. eta²=0.282는 Overall Score 변동의 28.2%가 어느 레퍼런스를 기준으로 삼았는지로 설명된다는 뜻이다.
A30: 주의: 본 설계는 반복측정(같은 문서가 15개 셀에 모두 등장) 구조를 갖는다. 이원분산분석은 이를 완전히 모델링하지 못하므로 06_ICC에서 문서 효과를 분리해 확인한다.

Sheet 05B_가정검정
A1: 분산분석의 가정 검정: 정규성과 등분산성 (논문 3.4)
A2: 이원분산분석이 전제하는 두 가정이 충족되는지 확인한다. 위반 시 비모수 검정으로 결론을 교차 확인한다.
A4: reference | B4: model | C4: n | D4: 평균 | E4: 중앙값 | F4: 표준편차 | G4: 왜도 | H4: 첨도(초과) | I4: Jarque-Bera | J4: p | K4: 정규성 | L4: Levene Z 평균
A5: chatgpt | B5: gemma | C5: =COUNTIFS('01_원자료'!$B$2:$B$976,$A5,'01_원자료'!$C$2:$C$976,$B5) -> 65 | D5: =AVERAGEIFS('01_원자료'!$S$2:$S$976,'01_원자료'!$B$2:$B$976,$A5,'01_원자료'!$C$2:$C$976,$B5) -> 0.55255117 | E5: =SUMPRODUCT(('01_원자료'!$B$2:$B$976=$A5)*('01_원자료'!$C$2:$C$976=$B5)*('01_원자료'!$Z$2:$Z$976=($C5+1)/2)*'01_원자료'!$S$2:$S$976) -> 0.5574037 | F5: =SQRT(SUMPRODUCT(('01_원자료'!$B$2:$B$976=$A5)*('01_원자료'!$C$2:$C$976=$B5)*('01_원자료'!$S$2:$S$976-$D5)^2)/($C5-1)) -> 0.025855541 | G5: =$C5/(($C5-1)*($C5-2))*SUMPRODUCT(('01_원자료'!$B$2:$B$976=$A5)*('01_원자료'!$C$2:$C$976=$B5)*(('01_원자료'!$S$2:$S$976-$D5)/$F5)^3) -> -0.91675894 | H5: =$C5*($C5+1)/(($C5-1)*($C5-2)*($C5-3))*SUMPRODUCT(('01_원자료'!$B$2:$B$976=$A5)*('01_원자료'!$C$2:$C$976=$B5)*(('01_원자료'!$S$2:$S$976-$D5)/$F5)^4)-3*($C5-1)^2/(($C5-2)*($C5-3)) -> 0.69662702 | I5: =$C5/6*(G5^2+H5^2/4) -> 10.419167 | J5: =CHIDIST(I5,2) -> 0.005463949 | K5: =IF(J5<0.05,"위반","충족") -> 위반 | L5: =AVERAGEIFS('01_원자료'!$AA$2:$AA$976,'01_원자료'!$B$2:$B$976,$A5,'01_원자료'!$C$2:$C$976,$B5) -> 0.018972171
A6: chatgpt | B6: ministral | C6: =COUNTIFS('01_원자료'!$B$2:$B$976,$A6,'01_원자료'!$C$2:$C$976,$B6) -> 65 | D6: =AVERAGEIFS('01_원자료'!$S$2:$S$976,'01_원자료'!$B$2:$B$976,$A6,'01_원자료'!$C$2:$C$976,$B6) -> 0.52754903 | E6: =SUMPRODUCT(('01_원자료'!$B$2:$B$976=$A6)*('01_원자료'!$C$2:$C$976=$B6)*('01_원자료'!$Z$2:$Z$976=($C6+1)/2)*'01_원자료'!$S$2:$S$976) -> 0.53129242 | F6: =SQRT(SUMPRODUCT(('01_원자료'!$B$2:$B$976=$A6)*('01_원자료'!$C$2:$C$976=$B6)*('01_원자료'!$S$2:$S$976-$D6)^2)/($C6-1)) -> 0.038793798 | G6: =$C6/(($C6-1)*($C6-2))*SUMPRODUCT(('01_원자료'!$B$2:$B$976=$A6)*('01_원자료'!$C$2:$C$976=$B6)*(('01_원자료'!$S$2:$S$976-$D6)/$F6)^3) -> 0.23326618 | H6: =$C6*($C6+1)/(($C6-1)*($C6-2)*($C6-3))*SUMPRODUCT(('01_원자료'!$B$2:$B$976=$A6)*('01_원자료'!$C$2:$C$976=$B6)*(('01_원자료'!$S$2:$S$976-$D6)/$F6)^4)-3*($C6-1)^2/(($C6-2)*($C6-3)) -> -0.81715257 | I6: =$C6/6*(G6^2+H6^2/4) -> 2.3979333 | J6: =CHIDIST(I6,2) -> 0.30150561 | K6: =IF(J6<0.05,"위반","충족") -> 충족 | L6: =AVERAGEIFS('01_원자료'!$AA$2:$AA$976,'01_원자료'!$B$2:$B$976,$A6,'01_원자료'!$C$2:$C$976,$B6) -> 0.032917357
A7: chatgpt | B7: qwen | C7: =COUNTIFS('01_원자료'!$B$2:$B$976,$A7,'01_원자료'!$C$2:$C$976,$B7) -> 65 | D7: =AVERAGEIFS('01_원자료'!$S$2:$S$976,'01_원자료'!$B$2:$B$976,$A7,'01_원자료'!$C$2:$C$976,$B7) -> 0.55645248 | E7: =SUMPRODUCT(('01_원자료'!$B$2:$B$976=$A7)*('01_원자료'!$C$2:$C$976=$B7)*('01_원자료'!$Z$2:$Z$976=($C7+1)/2)*'01_원자료'!$S$2:$S$976) -> 0.55302352 | F7: =SQRT(SUMPRODUCT(('01_원자료'!$B$2:$B$976=$A7)*('01_원자료'!$C$2:$C$976=$B7)*('01_원자료'!$S$2:$S$976-$D7)^2)/($C7-1)) -> 0.046617746 | G7: =$C7/(($C7-1)*($C7-2))*SUMPRODUCT(('01_원자료'!$B$2:$B$976=$A7)*('01_원자료'!$C$2:$C$976=$B7)*(('01_원자료'!$S$2:$S$976-$D7)/$F7)^3) -> -3.2379918 | H7: =$C7*($C7+1)/(($C7-1)*($C7-2)*($C7-3))*SUMPRODUCT(('01_원자료'!$B$2:$B$976=$A7)*('01_원자료'!$C$2:$C$976=$B7)*(('01_원자료'!$S$2:$S$976-$D7)/$F7)^4)-3*($C7-1)^2/(($C7-2)*($C7-3)) -> 20.287034 | I7: =$C7/6*(G7^2+H7^2/4) -> 1228.2349 | J7: =CHIDIST(I7,2) -> 1.9596933e-267 | K7: =IF(J7<0.05,"위반","충족") -> 위반 | L7: =AVERAGEIFS('01_원자료'!$AA$2:$AA$976,'01_원자료'!$B$2:$B$976,$A7,'01_원자료'!$C$2:$C$976,$B7) -> 0.027574558
A8: claude | B8: gemma | C8: =COUNTIFS('01_원자료'!$B$2:$B$976,$A8,'01_원자료'!$C$2:$C$976,$B8) -> 65 | D8: =AVERAGEIFS('01_원자료'!$S$2:$S$976,'01_원자료'!$B$2:$B$976,$A8,'01_원자료'!$C$2:$C$976,$B8) -> 0.6313027 | E8: =SUMPRODUCT(('01_원자료'!$B$2:$B$976=$A8)*('01_원자료'!$C$2:$C$976=$B8)*('01_원자료'!$Z$2:$Z$976=($C8+1)/2)*'01_원자료'!$S$2:$S$976) -> 0.62804896 | F8: =SQRT(SUMPRODUCT(('01_원자료'!$B$2:$B$976=$A8)*('01_원자료'!$C$2:$C$976=$B8)*('01_원자료'!$S$2:$S$976-$D8)^2)/($C8-1)) -> 0.026953734 | G8: =$C8/(($C8-1)*($C8-2))*SUMPRODUCT(('01_원자료'!$B$2:$B$976=$A8)*('01_원자료'!$C$2:$C$976=$B8)*(('01_원자료'!$S$2:$S$976-$D8)/$F8)^3) -> 0.68734435 | H8: =$C8*($C8+1)/(($C8-1)*($C8-2)*($C8-3))*SUMPRODUCT(('01_원자료'!$B$2:$B$976=$A8)*('01_원자료'!$C$2:$C$976=$B8)*(('01_원자료'!$S$2:$S$976-$D8)/$F8)^4)-3*($C8-1)^2/(($C8-2)*($C8-3)) -> 0.13944681 | I8: =$C8/6*(G8^2+H8^2/4) -> 5.1707891 | J8: =CHIDIST(I8,2) -> 0.075366338 | K8: =IF(J8<0.05,"위반","충족") -> 충족 | L8: =AVERAGEIFS('01_원자료'!$AA$2:$AA$976,'01_원자료'!$B$2:$B$976,$A8,'01_원자료'!$C$2:$C$976,$B8) -> 0.021179057
A9: claude | B9: ministral | C9: =COUNTIFS('01_원자료'!$B$2:$B$976,$A9,'01_원자료'!$C$2:$C$976,$B9) -> 65 | D9: =AVERAGEIFS('01_원자료'!$S$2:$S$976,'01_원자료'!$B$2:$B$976,$A9,'01_원자료'!$C$2:$C$976,$B9) -> 0.57489078 | E9: =SUMPRODUCT(('01_원자료'!$B$2:$B$976=$A9)*('01_원자료'!$C$2:$C$976=$B9)*('01_원자료'!$Z$2:$Z$976=($C9+1)/2)*'01_원자료'!$S$2:$S$976) -> 0.59082885 | F9: =SQRT(SUMPRODUCT(('01_원자료'!$B$2:$B$976=$A9)*('01_원자료'!$C$2:$C$976=$B9)*('01_원자료'!$S$2:$S$976-$D9)^2)/($C9-1)) -> 0.048893035 | G9: =$C9/(($C9-1)*($C9-2))*SUMPRODUCT(('01_원자료'!$B$2:$B$976=$A9)*('01_원자료'!$C$2:$C$976=$B9)*(('01_원자료'!$S$2:$S$976-$D9)/$F9)^3) -> -0.1349036 | H9: =$C9*($C9+1)/(($C9-1)*($C9-2)*($C9-3))*SUMPRODUCT(('01_원자료'!$B$2:$B$976=$A9)*('01_원자료'!$C$2:$C$976=$B9)*(('01_원자료'!$S$2:$S$976-$D9)/$F9)^4)-3*($C9-1)^2/(($C9-2)*($C9-3)) -> -1.5226316 | I9: =$C9/6*(G9^2+H9^2/4) -> 6.4761749 | J9: =CHIDIST(I9,2) -> 0.03923887 | K9: =IF(J9<0.05,"위반","충족") -> 위반 | L9: =AVERAGEIFS('01_원자료'!$AA$2:$AA$976,'01_원자료'!$B$2:$B$976,$A9,'01_원자료'!$C$2:$C$976,$B9) -> 0.044008154
A10: claude | B10: qwen | C10: =COUNTIFS('01_원자료'!$B$2:$B$976,$A10,'01_원자료'!$C$2:$C$976,$B10) -> 65 | D10: =AVERAGEIFS('01_원자료'!$S$2:$S$976,'01_원자료'!$B$2:$B$976,$A10,'01_원자료'!$C$2:$C$976,$B10) -> 0.65842301 | E10: =SUMPRODUCT(('01_원자료'!$B$2:$B$976=$A10)*('01_원자료'!$C$2:$C$976=$B10)*('01_원자료'!$Z$2:$Z$976=($C10+1)/2)*'01_원자료'!$S$2:$S$976) -> 0.66367732 | F10: =SQRT(SUMPRODUCT(('01_원자료'!$B$2:$B$976=$A10)*('01_원자료'!$C$2:$C$976=$B10)*('01_원자료'!$S$2:$S$976-$D10)^2)/($C10-1)) -> 0.054538232 | G10: =$C10/(($C10-1)*($C10-2))*SUMPRODUCT(('01_원자료'!$B$2:$B$976=$A10)*('01_원자료'!$C$2:$C$976=$B10)*(('01_원자료'!$S$2:$S$976-$D10)/$F10)^3) -> -4.6580083 | H10: =$C10*($C10+1)/(($C10-1)*($C10-2)*($C10-3))*SUMPRODUCT(('01_원자료'!$B$2:$B$976=$A10)*('01_원자료'!$C$2:$C$976=$B10)*(('01_원자료'!$S$2:$S$976-$D10)/$F10)^4)-3*($C10-1)^2/(($C10-2)*($C10-3)) -> 30.427155 | I10: =$C10/6*(G10^2+H10^2/4) -> 2742.4582 | J10: =CHIDIST(I10,2) -> 0 | K10: =IF(J10<0.05,"위반","충족") -> 위반 | L10: =AVERAGEIFS('01_원자료'!$AA$2:$AA$976,'01_원자료'!$B$2:$B$976,$A10,'01_원자료'!$C$2:$C$976,$B10) -> 0.029790732
A11: gemini | B11: gemma | C11: =COUNTIFS('01_원자료'!$B$2:$B$976,$A11,'01_원자료'!$C$2:$C$976,$B11) -> 65 | D11: =AVERAGEIFS('01_원자료'!$S$2:$S$976,'01_원자료'!$B$2:$B$976,$A11,'01_원자료'!$C$2:$C$976,$B11) -> 0.71765179 | E11: =SUMPRODUCT(('01_원자료'!$B$2:$B$976=$A11)*('01_원자료'!$C$2:$C$976=$B11)*('01_원자료'!$Z$2:$Z$976=($C11+1)/2)*'01_원자료'!$S$2:$S$976) -> 0.72943207 | F11: =SQRT(SUMPRODUCT(('01_원자료'!$B$2:$B$976=$A11)*('01_원자료'!$C$2:$C$976=$B11)*('01_원자료'!$S$2:$S$976-$D11)^2)/($C11-1)) -> 0.042246046 | G11: =$C11/(($C11-1)*($C11-2))*SUMPRODUCT(('01_원자료'!$B$2:$B$976=$A11)*('01_원자료'!$C$2:$C$976=$B11)*(('01_원자료'!$S$2:$S$976-$D11)/$F11)^3) -> -4.6018092 | H11: =$C11*($C11+1)/(($C11-1)*($C11-2)*($C11-3))*SUMPRODUCT(('01_원자료'!$B$2:$B$976=$A11)*('01_원자료'!$C$2:$C$976=$B11)*(('01_원자료'!$S$2:$S$976-$D11)/$F11)^4)-3*($C11-1)^2/(($C11-2)*($C11-3)) -> 28.926158 | I11: =$C11/6*(G11^2+H11^2/4) -> 2495.5375 | J11: =CHIDIST(I11,2) -> 0 | K11: =IF(J11<0.05,"위반","충족") -> 위반 | L11: =AVERAGEIFS('01_원자료'!$AA$2:$AA$976,'01_원자료'!$B$2:$B$976,$A11,'01_원자료'!$C$2:$C$976,$B11) -> 0.022974666
A12: gemini | B12: ministral | C12: =COUNTIFS('01_원자료'!$B$2:$B$976,$A12,'01_원자료'!$C$2:$C$976,$B12) -> 65 | D12: =AVERAGEIFS('01_원자료'!$S$2:$S$976,'01_원자료'!$B$2:$B$976,$A12,'01_원자료'!$C$2:$C$976,$B12) -> 0.57939907 | E12: =SUMPRODUCT(('01_원자료'!$B$2:$B$976=$A12)*('01_원자료'!$C$2:$C$976=$B12)*('01_원자료'!$Z$2:$Z$976=($C12+1)/2)*'01_원자료'!$S$2:$S$976) -> 0.59857949 | F12: =SQRT(SUMPRODUCT(('01_원자료'!$B$2:$B$976=$A12)*('01_원자료'!$C$2:$C$976=$B12)*('01_원자료'!$S$2:$S$976-$D12)^2)/($C12-1)) -> 0.050485672 | G12: =$C12/(($C12-1)*($C12-2))*SUMPRODUCT(('01_원자료'!$B$2:$B$976=$A12)*('01_원자료'!$C$2:$C$976=$B12)*(('01_원자료'!$S$2:$S$976-$D12)/$F12)^3) -> -0.58675539 | H12: =$C12*($C12+1)/(($C12-1)*($C12-2)*($C12-3))*SUMPRODUCT(('01_원자료'!$B$2:$B$976=$A12)*('01_원자료'!$C$2:$C$976=$B12)*(('01_원자료'!$S$2:$S$976-$D12)/$F12)^4)-3*($C12-1)^2/(($C12-2)*($C12-3)) -> 0.33680202 | I12: =$C12/6*(G12^2+H12^2/4) -> 4.0369419 | J12: =CHIDIST(I12,2) -> 0.13285846 | K12: =IF(J12<0.05,"위반","충족") -> 충족 | L12: =AVERAGEIFS('01_원자료'!$AA$2:$AA$976,'01_원자료'!$B$2:$B$976,$A12,'01_원자료'!$C$2:$C$976,$B12) -> 0.043405892
A13: gemini | B13: qwen | C13: =COUNTIFS('01_원자료'!$B$2:$B$976,$A13,'01_원자료'!$C$2:$C$976,$B13) -> 65 | D13: =AVERAGEIFS('01_원자료'!$S$2:$S$976,'01_원자료'!$B$2:$B$976,$A13,'01_원자료'!$C$2:$C$976,$B13) -> 0.68823698 | E13: =SUMPRODUCT(('01_원자료'!$B$2:$B$976=$A13)*('01_원자료'!$C$2:$C$976=$B13)*('01_원자료'!$Z$2:$Z$976=($C13+1)/2)*'01_원자료'!$S$2:$S$976) -> 0.69231984 | F13: =SQRT(SUMPRODUCT(('01_원자료'!$B$2:$B$976=$A13)*('01_원자료'!$C$2:$C$976=$B13)*('01_원자료'!$S$2:$S$976-$D13)^2)/($C13-1)) -> 0.070731189 | G13: =$C13/(($C13-1)*($C13-2))*SUMPRODUCT(('01_원자료'!$B$2:$B$976=$A13)*('01_원자료'!$C$2:$C$976=$B13)*(('01_원자료'!$S$2:$S$976-$D13)/$F13)^3) -> -2.9477042 | H13: =$C13*($C13+1)/(($C13-1)*($C13-2)*($C13-3))*SUMPRODUCT(('01_원자료'!$B$2:$B$976=$A13)*('01_원자료'!$C$2:$C$976=$B13)*(('01_원자료'!$S$2:$S$976-$D13)/$F13)^4)-3*($C13-1)^2/(($C13-2)*($C13-3)) -> 13.834347 | I13: =$C13/6*(G13^2+H13^2/4) -> 612.47603 | J13: =CHIDIST(I13,2) -> 1.0058212e-133 | K13: =IF(J13<0.05,"위반","충족") -> 위반 | L13: =AVERAGEIFS('01_원자료'!$AA$2:$AA$976,'01_원자료'!$B$2:$B$976,$A13,'01_원자료'!$C$2:$C$976,$B13) -> 0.042879615
A14: mistral | B14: gemma | C14: =COUNTIFS('01_원자료'!$B$2:$B$976,$A14,'01_원자료'!$C$2:$C$976,$B14) -> 65 | D14: =AVERAGEIFS('01_원자료'!$S$2:$S$976,'01_원자료'!$B$2:$B$976,$A14,'01_원자료'!$C$2:$C$976,$B14) -> 0.62288162 | E14: =SUMPRODUCT(('01_원자료'!$B$2:$B$976=$A14)*('01_원자료'!$C$2:$C$976=$B14)*('01_원자료'!$Z$2:$Z$976=($C14+1)/2)*'01_원자료'!$S$2:$S$976) -> 0.63935295 | F14: =SQRT(SUMPRODUCT(('01_원자료'!$B$2:$B$976=$A14)*('01_원자료'!$C$2:$C$976=$B14)*('01_원자료'!$S$2:$S$976-$D14)^2)/($C14-1)) -> 0.043075519 | G14: =$C14/(($C14-1)*($C14-2))*SUMPRODUCT(('01_원자료'!$B$2:$B$976=$A14)*('01_원자료'!$C$2:$C$976=$B14)*(('01_원자료'!$S$2:$S$976-$D14)/$F14)^3) -> -0.47691921 | H14: =$C14*($C14+1)/(($C14-1)*($C14-2)*($C14-3))*SUMPRODUCT(('01_원자료'!$B$2:$B$976=$A14)*('01_원자료'!$C$2:$C$976=$B14)*(('01_원자료'!$S$2:$S$976-$D14)/$F14)^4)-3*($C14-1)^2/(($C14-2)*($C14-3)) -> -1.1682312 | I14: =$C14/6*(G14^2+H14^2/4) -> 6.1602987 | J14: =CHIDIST(I14,2) -> 0.045952393 | K14: =IF(J14<0.05,"위반","충족") -> 위반 | L14: =AVERAGEIFS('01_원자료'!$AA$2:$AA$976,'01_원자료'!$B$2:$B$976,$A14,'01_원자료'!$C$2:$C$976,$B14) -> 0.036658073
